2022-01-28 00:11:24,091 INFO    MainThread:1362264 [internal.py:wandb_internal():87] W&B internal server running at pid: 1362264, started at: 2022-01-28 00:11:24.090807
2022-01-28 00:11:24,092 DEBUG   HandlerThread:1362264 [handler.py:handle_request():130] handle_request: check_version
2022-01-28 00:11:24,092 INFO    WriterThread:1362264 [datastore.py:open_for_write():77] open: /home/runnphoenix/work/flatland-rl/rainbow/wandb/run-20220128_001123-1lwizexr/run-1lwizexr.wandb
2022-01-28 00:11:24,094 DEBUG   SenderThread:1362264 [sender.py:send():238] send: header
2022-01-28 00:11:24,094 DEBUG   SenderThread:1362264 [sender.py:send_request():252] send_request: check_version
2022-01-28 00:11:25,605 DEBUG   SenderThread:1362264 [sender.py:send():238] send: run
2022-01-28 00:11:30,015 ERROR   SenderThread:1362264 [retry.py:__call__():126] Retry attempt failed:
Traceback (most recent call last):
  File "/home/runnphoenix/anaconda3/lib/python3.8/site-packages/urllib3/connectionpool.py", line 696, in urlopen
    self._prepare_proxy(conn)
  File "/home/runnphoenix/anaconda3/lib/python3.8/site-packages/urllib3/connectionpool.py", line 964, in _prepare_proxy
    conn.connect()
  File "/home/runnphoenix/anaconda3/lib/python3.8/site-packages/urllib3/connection.py", line 411, in connect
    self.sock = ssl_wrap_socket(
  File "/home/runnphoenix/anaconda3/lib/python3.8/site-packages/urllib3/util/ssl_.py", line 428, in ssl_wrap_socket
    ssl_sock = _ssl_wrap_socket_impl(
  File "/home/runnphoenix/anaconda3/lib/python3.8/site-packages/urllib3/util/ssl_.py", line 472, in _ssl_wrap_socket_impl
    return ssl_context.wrap_socket(sock, server_hostname=server_hostname)
  File "/home/runnphoenix/anaconda3/lib/python3.8/ssl.py", line 500, in wrap_socket
    return self.sslsocket_class._create(
  File "/home/runnphoenix/anaconda3/lib/python3.8/ssl.py", line 1040, in _create
    self.do_handshake()
  File "/home/runnphoenix/anaconda3/lib/python3.8/ssl.py", line 1309, in do_handshake
    self._sslobj.do_handshake()
OSError: [Errno 0] Error

During handling of the above exception, another exception occurred:

Traceback (most recent call last):
  File "/home/runnphoenix/anaconda3/lib/python3.8/site-packages/requests/adapters.py", line 439, in send
    resp = conn.urlopen(
  File "/home/runnphoenix/anaconda3/lib/python3.8/site-packages/urllib3/connectionpool.py", line 755, in urlopen
    retries = retries.increment(
  File "/home/runnphoenix/anaconda3/lib/python3.8/site-packages/urllib3/util/retry.py", line 573, in increment
    raise MaxRetryError(_pool, url, error or ResponseError(cause))
urllib3.exceptions.MaxRetryError: HTTPSConnectionPool(host='api.wandb.ai', port=443): Max retries exceeded with url: /graphql (Caused by ProxyError('Cannot connect to proxy.', OSError(0, 'Error')))

During handling of the above exception, another exception occurred:

Traceback (most recent call last):
  File "/home/runnphoenix/anaconda3/lib/python3.8/site-packages/wandb/sdk/lib/retry.py", line 102, in __call__
    result = self._call_fn(*args, **kwargs)
  File "/home/runnphoenix/anaconda3/lib/python3.8/site-packages/wandb/sdk/internal/internal_api.py", line 141, in execute
    return self.client.execute(*args, **kwargs)
  File "/home/runnphoenix/anaconda3/lib/python3.8/site-packages/wandb/vendor/gql-0.2.0/gql/client.py", line 52, in execute
    result = self._get_result(document, *args, **kwargs)
  File "/home/runnphoenix/anaconda3/lib/python3.8/site-packages/wandb/vendor/gql-0.2.0/gql/client.py", line 60, in _get_result
    return self.transport.execute(document, *args, **kwargs)
  File "/home/runnphoenix/anaconda3/lib/python3.8/site-packages/wandb/vendor/gql-0.2.0/gql/transport/requests.py", line 38, in execute
    request = requests.post(self.url, **post_args)
  File "/home/runnphoenix/anaconda3/lib/python3.8/site-packages/requests/api.py", line 119, in post
    return request('post', url, data=data, json=json, **kwargs)
  File "/home/runnphoenix/anaconda3/lib/python3.8/site-packages/requests/api.py", line 61, in request
    return session.request(method=method, url=url, **kwargs)
  File "/home/runnphoenix/anaconda3/lib/python3.8/site-packages/requests/sessions.py", line 542, in request
    resp = self.send(prep, **send_kwargs)
  File "/home/runnphoenix/anaconda3/lib/python3.8/site-packages/requests/sessions.py", line 655, in send
    r = adapter.send(request, **kwargs)
  File "/home/runnphoenix/anaconda3/lib/python3.8/site-packages/requests/adapters.py", line 510, in send
    raise ProxyError(e, request=request)
requests.exceptions.ProxyError: HTTPSConnectionPool(host='api.wandb.ai', port=443): Max retries exceeded with url: /graphql (Caused by ProxyError('Cannot connect to proxy.', OSError(0, 'Error')))
2022-01-28 00:11:55,606 DEBUG   HandlerThread:1362264 [handler.py:handle_request():130] handle_request: shutdown
2022-01-28 00:11:55,606 INFO    HandlerThread:1362264 [handler.py:finish():731] shutting down handler
2022-01-28 00:11:55,616 INFO    WriterThread:1362264 [datastore.py:close():281] close: /home/runnphoenix/work/flatland-rl/rainbow/wandb/run-20220128_001123-1lwizexr/run-1lwizexr.wandb
2022-01-28 00:12:25,410 INFO    SenderThread:1362264 [dir_watcher.py:__init__():169] watching files in: /home/runnphoenix/work/flatland-rl/rainbow/wandb/run-20220128_001123-1lwizexr/files
2022-01-28 00:12:25,410 INFO    SenderThread:1362264 [sender.py:_start_run_threads():825] run started: 1lwizexr with start time 1643299883
2022-01-28 00:12:25,410 INFO    SenderThread:1362264 [sender.py:finish():1091] shutting down sender
2022-01-28 00:12:25,410 INFO    SenderThread:1362264 [dir_watcher.py:finish():283] shutting down directory watcher
2022-01-28 00:12:26,410 INFO    SenderThread:1362264 [dir_watcher.py:finish():313] scan: /home/runnphoenix/work/flatland-rl/rainbow/wandb/run-20220128_001123-1lwizexr/files
2022-01-28 00:12:26,410 INFO    SenderThread:1362264 [dir_watcher.py:finish():327] scan save: /home/runnphoenix/work/flatland-rl/rainbow/wandb/run-20220128_001123-1lwizexr/files/config.yaml config.yaml
2022-01-28 00:12:26,410 INFO    SenderThread:1362264 [file_pusher.py:finish():177] shutting down file pusher
2022-01-28 00:12:26,410 INFO    SenderThread:1362264 [file_pusher.py:join():182] waiting for file pusher
2022-01-28 00:12:40,887 ERROR   Thread-10 :1362264 [internal_api.py:upload_file():1546] upload_file exception https://storage.googleapis.com/wandb-production.appspot.com/runnphoenix/Flatland-flatland-multi-agent/1lwizexr/config.yaml?Expires=1643386352&GoogleAccessId=wandb-production%40appspot.gserviceaccount.com&Signature=d0Q6tcfGDB8GV%2Bv2A1Fijdoz%2FzH4Ch3lu8p6ohMpkqRvKw8LfBdY6r6SoS2sdzRjsvaU6UCP5GZUdcs%2Bb3Vi%2FBr4%2FY15gGHOIBKuRZL7%2Fp0hwRf3%2Fo4Jc5czTWrNEZXUQtUr7AQ2vzl1kazay0m0TTMHNtj5VR8Xr7IiDd3zDuPKI8wmA1uNlmrFjsgZjnBmiBIZBosFNfIjpXE7T2iyGnBSvSJSMbr4LGrzf0BAyNcT0caIb088JSmDbPJTZVLQ2zPNIpQANQDEv2e7GS4%2FUCscI6amQNs9kRvTDH6l%2BRPgDuiYibXSvjlhpFodfLxnKQzShOK4%2B8xCCtOJGHzYXw%3D%3D HTTPSConnectionPool(host='storage.googleapis.com', port=443): Max retries exceeded with url: /wandb-production.appspot.com/runnphoenix/Flatland-flatland-multi-agent/1lwizexr/config.yaml?Expires=1643386352&GoogleAccessId=wandb-production%40appspot.gserviceaccount.com&Signature=d0Q6tcfGDB8GV%2Bv2A1Fijdoz%2FzH4Ch3lu8p6ohMpkqRvKw8LfBdY6r6SoS2sdzRjsvaU6UCP5GZUdcs%2Bb3Vi%2FBr4%2FY15gGHOIBKuRZL7%2Fp0hwRf3%2Fo4Jc5czTWrNEZXUQtUr7AQ2vzl1kazay0m0TTMHNtj5VR8Xr7IiDd3zDuPKI8wmA1uNlmrFjsgZjnBmiBIZBosFNfIjpXE7T2iyGnBSvSJSMbr4LGrzf0BAyNcT0caIb088JSmDbPJTZVLQ2zPNIpQANQDEv2e7GS4%2FUCscI6amQNs9kRvTDH6l%2BRPgDuiYibXSvjlhpFodfLxnKQzShOK4%2B8xCCtOJGHzYXw%3D%3D (Caused by ProxyError('Cannot connect to proxy.', OSError(0, 'Error')))
2022-01-28 00:12:42,863 ERROR   Thread-10 :1362264 [internal_api.py:upload_file():1546] upload_file exception https://storage.googleapis.com/wandb-production.appspot.com/runnphoenix/Flatland-flatland-multi-agent/1lwizexr/config.yaml?Expires=1643386352&GoogleAccessId=wandb-production%40appspot.gserviceaccount.com&Signature=d0Q6tcfGDB8GV%2Bv2A1Fijdoz%2FzH4Ch3lu8p6ohMpkqRvKw8LfBdY6r6SoS2sdzRjsvaU6UCP5GZUdcs%2Bb3Vi%2FBr4%2FY15gGHOIBKuRZL7%2Fp0hwRf3%2Fo4Jc5czTWrNEZXUQtUr7AQ2vzl1kazay0m0TTMHNtj5VR8Xr7IiDd3zDuPKI8wmA1uNlmrFjsgZjnBmiBIZBosFNfIjpXE7T2iyGnBSvSJSMbr4LGrzf0BAyNcT0caIb088JSmDbPJTZVLQ2zPNIpQANQDEv2e7GS4%2FUCscI6amQNs9kRvTDH6l%2BRPgDuiYibXSvjlhpFodfLxnKQzShOK4%2B8xCCtOJGHzYXw%3D%3D HTTPSConnectionPool(host='storage.googleapis.com', port=443): Max retries exceeded with url: /wandb-production.appspot.com/runnphoenix/Flatland-flatland-multi-agent/1lwizexr/config.yaml?Expires=1643386352&GoogleAccessId=wandb-production%40appspot.gserviceaccount.com&Signature=d0Q6tcfGDB8GV%2Bv2A1Fijdoz%2FzH4Ch3lu8p6ohMpkqRvKw8LfBdY6r6SoS2sdzRjsvaU6UCP5GZUdcs%2Bb3Vi%2FBr4%2FY15gGHOIBKuRZL7%2Fp0hwRf3%2Fo4Jc5czTWrNEZXUQtUr7AQ2vzl1kazay0m0TTMHNtj5VR8Xr7IiDd3zDuPKI8wmA1uNlmrFjsgZjnBmiBIZBosFNfIjpXE7T2iyGnBSvSJSMbr4LGrzf0BAyNcT0caIb088JSmDbPJTZVLQ2zPNIpQANQDEv2e7GS4%2FUCscI6amQNs9kRvTDH6l%2BRPgDuiYibXSvjlhpFodfLxnKQzShOK4%2B8xCCtOJGHzYXw%3D%3D (Caused by ProxyError('Cannot connect to proxy.', OSError(0, 'Error')))
2022-01-28 00:12:46,923 ERROR   Thread-10 :1362264 [internal_api.py:upload_file():1546] upload_file exception https://storage.googleapis.com/wandb-production.appspot.com/runnphoenix/Flatland-flatland-multi-agent/1lwizexr/config.yaml?Expires=1643386352&GoogleAccessId=wandb-production%40appspot.gserviceaccount.com&Signature=d0Q6tcfGDB8GV%2Bv2A1Fijdoz%2FzH4Ch3lu8p6ohMpkqRvKw8LfBdY6r6SoS2sdzRjsvaU6UCP5GZUdcs%2Bb3Vi%2FBr4%2FY15gGHOIBKuRZL7%2Fp0hwRf3%2Fo4Jc5czTWrNEZXUQtUr7AQ2vzl1kazay0m0TTMHNtj5VR8Xr7IiDd3zDuPKI8wmA1uNlmrFjsgZjnBmiBIZBosFNfIjpXE7T2iyGnBSvSJSMbr4LGrzf0BAyNcT0caIb088JSmDbPJTZVLQ2zPNIpQANQDEv2e7GS4%2FUCscI6amQNs9kRvTDH6l%2BRPgDuiYibXSvjlhpFodfLxnKQzShOK4%2B8xCCtOJGHzYXw%3D%3D HTTPSConnectionPool(host='storage.googleapis.com', port=443): Max retries exceeded with url: /wandb-production.appspot.com/runnphoenix/Flatland-flatland-multi-agent/1lwizexr/config.yaml?Expires=1643386352&GoogleAccessId=wandb-production%40appspot.gserviceaccount.com&Signature=d0Q6tcfGDB8GV%2Bv2A1Fijdoz%2FzH4Ch3lu8p6ohMpkqRvKw8LfBdY6r6SoS2sdzRjsvaU6UCP5GZUdcs%2Bb3Vi%2FBr4%2FY15gGHOIBKuRZL7%2Fp0hwRf3%2Fo4Jc5czTWrNEZXUQtUr7AQ2vzl1kazay0m0TTMHNtj5VR8Xr7IiDd3zDuPKI8wmA1uNlmrFjsgZjnBmiBIZBosFNfIjpXE7T2iyGnBSvSJSMbr4LGrzf0BAyNcT0caIb088JSmDbPJTZVLQ2zPNIpQANQDEv2e7GS4%2FUCscI6amQNs9kRvTDH6l%2BRPgDuiYibXSvjlhpFodfLxnKQzShOK4%2B8xCCtOJGHzYXw%3D%3D (Caused by ProxyError('Cannot connect to proxy.', OSError(0, 'Error')))
2022-01-28 00:12:46,923 ERROR   Thread-10 :1362264 [retry.py:__call__():126] Retry attempt failed:
Traceback (most recent call last):
  File "/home/runnphoenix/anaconda3/lib/python3.8/site-packages/urllib3/connectionpool.py", line 696, in urlopen
    self._prepare_proxy(conn)
  File "/home/runnphoenix/anaconda3/lib/python3.8/site-packages/urllib3/connectionpool.py", line 964, in _prepare_proxy
    conn.connect()
  File "/home/runnphoenix/anaconda3/lib/python3.8/site-packages/urllib3/connection.py", line 411, in connect
    self.sock = ssl_wrap_socket(
  File "/home/runnphoenix/anaconda3/lib/python3.8/site-packages/urllib3/util/ssl_.py", line 428, in ssl_wrap_socket
    ssl_sock = _ssl_wrap_socket_impl(
  File "/home/runnphoenix/anaconda3/lib/python3.8/site-packages/urllib3/util/ssl_.py", line 472, in _ssl_wrap_socket_impl
    return ssl_context.wrap_socket(sock, server_hostname=server_hostname)
  File "/home/runnphoenix/anaconda3/lib/python3.8/ssl.py", line 500, in wrap_socket
    return self.sslsocket_class._create(
  File "/home/runnphoenix/anaconda3/lib/python3.8/ssl.py", line 1040, in _create
    self.do_handshake()
  File "/home/runnphoenix/anaconda3/lib/python3.8/ssl.py", line 1309, in do_handshake
    self._sslobj.do_handshake()
OSError: [Errno 0] Error

During handling of the above exception, another exception occurred:

Traceback (most recent call last):
  File "/home/runnphoenix/anaconda3/lib/python3.8/site-packages/requests/adapters.py", line 439, in send
    resp = conn.urlopen(
  File "/home/runnphoenix/anaconda3/lib/python3.8/site-packages/urllib3/connectionpool.py", line 755, in urlopen
    retries = retries.increment(
  File "/home/runnphoenix/anaconda3/lib/python3.8/site-packages/urllib3/util/retry.py", line 573, in increment
    raise MaxRetryError(_pool, url, error or ResponseError(cause))
urllib3.exceptions.MaxRetryError: HTTPSConnectionPool(host='storage.googleapis.com', port=443): Max retries exceeded with url: /wandb-production.appspot.com/runnphoenix/Flatland-flatland-multi-agent/1lwizexr/config.yaml?Expires=1643386352&GoogleAccessId=wandb-production%40appspot.gserviceaccount.com&Signature=d0Q6tcfGDB8GV%2Bv2A1Fijdoz%2FzH4Ch3lu8p6ohMpkqRvKw8LfBdY6r6SoS2sdzRjsvaU6UCP5GZUdcs%2Bb3Vi%2FBr4%2FY15gGHOIBKuRZL7%2Fp0hwRf3%2Fo4Jc5czTWrNEZXUQtUr7AQ2vzl1kazay0m0TTMHNtj5VR8Xr7IiDd3zDuPKI8wmA1uNlmrFjsgZjnBmiBIZBosFNfIjpXE7T2iyGnBSvSJSMbr4LGrzf0BAyNcT0caIb088JSmDbPJTZVLQ2zPNIpQANQDEv2e7GS4%2FUCscI6amQNs9kRvTDH6l%2BRPgDuiYibXSvjlhpFodfLxnKQzShOK4%2B8xCCtOJGHzYXw%3D%3D (Caused by ProxyError('Cannot connect to proxy.', OSError(0, 'Error')))

During handling of the above exception, another exception occurred:

Traceback (most recent call last):
  File "/home/runnphoenix/anaconda3/lib/python3.8/site-packages/wandb/sdk/internal/internal_api.py", line 1543, in upload_file
    response = requests.put(url, data=progress, headers=extra_headers)
  File "/home/runnphoenix/anaconda3/lib/python3.8/site-packages/requests/api.py", line 134, in put
    return request('put', url, data=data, **kwargs)
  File "/home/runnphoenix/anaconda3/lib/python3.8/site-packages/requests/api.py", line 61, in request
    return session.request(method=method, url=url, **kwargs)
  File "/home/runnphoenix/anaconda3/lib/python3.8/site-packages/requests/sessions.py", line 542, in request
    resp = self.send(prep, **send_kwargs)
  File "/home/runnphoenix/anaconda3/lib/python3.8/site-packages/requests/sessions.py", line 655, in send
    r = adapter.send(request, **kwargs)
  File "/home/runnphoenix/anaconda3/lib/python3.8/site-packages/requests/adapters.py", line 510, in send
    raise ProxyError(e, request=request)
requests.exceptions.ProxyError: HTTPSConnectionPool(host='storage.googleapis.com', port=443): Max retries exceeded with url: /wandb-production.appspot.com/runnphoenix/Flatland-flatland-multi-agent/1lwizexr/config.yaml?Expires=1643386352&GoogleAccessId=wandb-production%40appspot.gserviceaccount.com&Signature=d0Q6tcfGDB8GV%2Bv2A1Fijdoz%2FzH4Ch3lu8p6ohMpkqRvKw8LfBdY6r6SoS2sdzRjsvaU6UCP5GZUdcs%2Bb3Vi%2FBr4%2FY15gGHOIBKuRZL7%2Fp0hwRf3%2Fo4Jc5czTWrNEZXUQtUr7AQ2vzl1kazay0m0TTMHNtj5VR8Xr7IiDd3zDuPKI8wmA1uNlmrFjsgZjnBmiBIZBosFNfIjpXE7T2iyGnBSvSJSMbr4LGrzf0BAyNcT0caIb088JSmDbPJTZVLQ2zPNIpQANQDEv2e7GS4%2FUCscI6amQNs9kRvTDH6l%2BRPgDuiYibXSvjlhpFodfLxnKQzShOK4%2B8xCCtOJGHzYXw%3D%3D (Caused by ProxyError('Cannot connect to proxy.', OSError(0, 'Error')))

During handling of the above exception, another exception occurred:

Traceback (most recent call last):
  File "/home/runnphoenix/anaconda3/lib/python3.8/site-packages/wandb/sdk/lib/retry.py", line 102, in __call__
    result = self._call_fn(*args, **kwargs)
  File "/home/runnphoenix/anaconda3/lib/python3.8/site-packages/wandb/sdk/internal/internal_api.py", line 1555, in upload_file
    six.reraise(type(e), e, sys.exc_info()[2])
  File "/home/runnphoenix/anaconda3/lib/python3.8/site-packages/six.py", line 702, in reraise
    raise value.with_traceback(tb)
  File "/home/runnphoenix/anaconda3/lib/python3.8/site-packages/wandb/sdk/internal/internal_api.py", line 1543, in upload_file
    response = requests.put(url, data=progress, headers=extra_headers)
  File "/home/runnphoenix/anaconda3/lib/python3.8/site-packages/requests/api.py", line 134, in put
    return request('put', url, data=data, **kwargs)
  File "/home/runnphoenix/anaconda3/lib/python3.8/site-packages/requests/api.py", line 61, in request
    return session.request(method=method, url=url, **kwargs)
  File "/home/runnphoenix/anaconda3/lib/python3.8/site-packages/requests/sessions.py", line 542, in request
    resp = self.send(prep, **send_kwargs)
  File "/home/runnphoenix/anaconda3/lib/python3.8/site-packages/requests/sessions.py", line 655, in send
    r = adapter.send(request, **kwargs)
  File "/home/runnphoenix/anaconda3/lib/python3.8/site-packages/requests/adapters.py", line 510, in send
    raise ProxyError(e, request=request)
wandb.sdk.lib.retry.TransientError: None
2022-01-28 00:12:53,286 ERROR   Thread-10 :1362264 [internal_api.py:upload_file():1546] upload_file exception https://storage.googleapis.com/wandb-production.appspot.com/runnphoenix/Flatland-flatland-multi-agent/1lwizexr/config.yaml?Expires=1643386352&GoogleAccessId=wandb-production%40appspot.gserviceaccount.com&Signature=d0Q6tcfGDB8GV%2Bv2A1Fijdoz%2FzH4Ch3lu8p6ohMpkqRvKw8LfBdY6r6SoS2sdzRjsvaU6UCP5GZUdcs%2Bb3Vi%2FBr4%2FY15gGHOIBKuRZL7%2Fp0hwRf3%2Fo4Jc5czTWrNEZXUQtUr7AQ2vzl1kazay0m0TTMHNtj5VR8Xr7IiDd3zDuPKI8wmA1uNlmrFjsgZjnBmiBIZBosFNfIjpXE7T2iyGnBSvSJSMbr4LGrzf0BAyNcT0caIb088JSmDbPJTZVLQ2zPNIpQANQDEv2e7GS4%2FUCscI6amQNs9kRvTDH6l%2BRPgDuiYibXSvjlhpFodfLxnKQzShOK4%2B8xCCtOJGHzYXw%3D%3D HTTPSConnectionPool(host='storage.googleapis.com', port=443): Max retries exceeded with url: /wandb-production.appspot.com/runnphoenix/Flatland-flatland-multi-agent/1lwizexr/config.yaml?Expires=1643386352&GoogleAccessId=wandb-production%40appspot.gserviceaccount.com&Signature=d0Q6tcfGDB8GV%2Bv2A1Fijdoz%2FzH4Ch3lu8p6ohMpkqRvKw8LfBdY6r6SoS2sdzRjsvaU6UCP5GZUdcs%2Bb3Vi%2FBr4%2FY15gGHOIBKuRZL7%2Fp0hwRf3%2Fo4Jc5czTWrNEZXUQtUr7AQ2vzl1kazay0m0TTMHNtj5VR8Xr7IiDd3zDuPKI8wmA1uNlmrFjsgZjnBmiBIZBosFNfIjpXE7T2iyGnBSvSJSMbr4LGrzf0BAyNcT0caIb088JSmDbPJTZVLQ2zPNIpQANQDEv2e7GS4%2FUCscI6amQNs9kRvTDH6l%2BRPgDuiYibXSvjlhpFodfLxnKQzShOK4%2B8xCCtOJGHzYXw%3D%3D (Caused by ProxyError('Cannot connect to proxy.', OSError(0, 'Error')))
2022-01-28 00:12:56,734 WARNING FileStreamThread:1362264 [file_stream.py:request_with_retry():461] requests_with_retry encountered retryable exception: HTTPSConnectionPool(host='api.wandb.ai', port=443): Max retries exceeded with url: /files/runnphoenix/Flatland-flatland-multi-agent/1lwizexr/file_stream (Caused by ProxyError('Cannot connect to proxy.', OSError(0, 'Error'))). func: <bound method Session.post of <requests.sessions.Session object at 0x7fcaccb7cb80>>, args: ('https://api.wandb.ai/files/runnphoenix/Flatland-flatland-multi-agent/1lwizexr/file_stream',), kwargs: {'json': {'complete': False, 'failed': False, 'dropped': 0, 'uploaded': []}}
2022-01-28 00:12:59,545 WARNING FileStreamThread:1362264 [file_stream.py:request_with_retry():461] requests_with_retry encountered retryable exception: HTTPSConnectionPool(host='api.wandb.ai', port=443): Max retries exceeded with url: /files/runnphoenix/Flatland-flatland-multi-agent/1lwizexr/file_stream (Caused by ProxyError('Cannot connect to proxy.', OSError(0, 'Error'))). func: <bound method Session.post of <requests.sessions.Session object at 0x7fcaccb7cb80>>, args: ('https://api.wandb.ai/files/runnphoenix/Flatland-flatland-multi-agent/1lwizexr/file_stream',), kwargs: {'json': {'complete': False, 'failed': False, 'dropped': 0, 'uploaded': []}}
2022-01-28 00:13:02,982 ERROR   Thread-10 :1362264 [internal_api.py:upload_file():1546] upload_file exception https://storage.googleapis.com/wandb-production.appspot.com/runnphoenix/Flatland-flatland-multi-agent/1lwizexr/config.yaml?Expires=1643386352&GoogleAccessId=wandb-production%40appspot.gserviceaccount.com&Signature=d0Q6tcfGDB8GV%2Bv2A1Fijdoz%2FzH4Ch3lu8p6ohMpkqRvKw8LfBdY6r6SoS2sdzRjsvaU6UCP5GZUdcs%2Bb3Vi%2FBr4%2FY15gGHOIBKuRZL7%2Fp0hwRf3%2Fo4Jc5czTWrNEZXUQtUr7AQ2vzl1kazay0m0TTMHNtj5VR8Xr7IiDd3zDuPKI8wmA1uNlmrFjsgZjnBmiBIZBosFNfIjpXE7T2iyGnBSvSJSMbr4LGrzf0BAyNcT0caIb088JSmDbPJTZVLQ2zPNIpQANQDEv2e7GS4%2FUCscI6amQNs9kRvTDH6l%2BRPgDuiYibXSvjlhpFodfLxnKQzShOK4%2B8xCCtOJGHzYXw%3D%3D HTTPSConnectionPool(host='storage.googleapis.com', port=443): Max retries exceeded with url: /wandb-production.appspot.com/runnphoenix/Flatland-flatland-multi-agent/1lwizexr/config.yaml?Expires=1643386352&GoogleAccessId=wandb-production%40appspot.gserviceaccount.com&Signature=d0Q6tcfGDB8GV%2Bv2A1Fijdoz%2FzH4Ch3lu8p6ohMpkqRvKw8LfBdY6r6SoS2sdzRjsvaU6UCP5GZUdcs%2Bb3Vi%2FBr4%2FY15gGHOIBKuRZL7%2Fp0hwRf3%2Fo4Jc5czTWrNEZXUQtUr7AQ2vzl1kazay0m0TTMHNtj5VR8Xr7IiDd3zDuPKI8wmA1uNlmrFjsgZjnBmiBIZBosFNfIjpXE7T2iyGnBSvSJSMbr4LGrzf0BAyNcT0caIb088JSmDbPJTZVLQ2zPNIpQANQDEv2e7GS4%2FUCscI6amQNs9kRvTDH6l%2BRPgDuiYibXSvjlhpFodfLxnKQzShOK4%2B8xCCtOJGHzYXw%3D%3D (Caused by ProxyError('Cannot connect to proxy.', OSError(0, 'Error')))
2022-01-28 00:13:04,504 WARNING FileStreamThread:1362264 [file_stream.py:request_with_retry():461] requests_with_retry encountered retryable exception: HTTPSConnectionPool(host='api.wandb.ai', port=443): Max retries exceeded with url: /files/runnphoenix/Flatland-flatland-multi-agent/1lwizexr/file_stream (Caused by ProxyError('Cannot connect to proxy.', OSError(0, 'Error'))). func: <bound method Session.post of <requests.sessions.Session object at 0x7fcaccb7cb80>>, args: ('https://api.wandb.ai/files/runnphoenix/Flatland-flatland-multi-agent/1lwizexr/file_stream',), kwargs: {'json': {'complete': False, 'failed': False, 'dropped': 0, 'uploaded': []}}
2022-01-28 00:13:14,154 WARNING FileStreamThread:1362264 [file_stream.py:request_with_retry():461] requests_with_retry encountered retryable exception: HTTPSConnectionPool(host='api.wandb.ai', port=443): Max retries exceeded with url: /files/runnphoenix/Flatland-flatland-multi-agent/1lwizexr/file_stream (Caused by ProxyError('Cannot connect to proxy.', OSError(0, 'Error'))). func: <bound method Session.post of <requests.sessions.Session object at 0x7fcaccb7cb80>>, args: ('https://api.wandb.ai/files/runnphoenix/Flatland-flatland-multi-agent/1lwizexr/file_stream',), kwargs: {'json': {'complete': False, 'failed': False, 'dropped': 0, 'uploaded': []}}
2022-01-28 00:13:22,978 ERROR   Thread-10 :1362264 [internal_api.py:upload_file():1546] upload_file exception https://storage.googleapis.com/wandb-production.appspot.com/runnphoenix/Flatland-flatland-multi-agent/1lwizexr/config.yaml?Expires=1643386352&GoogleAccessId=wandb-production%40appspot.gserviceaccount.com&Signature=d0Q6tcfGDB8GV%2Bv2A1Fijdoz%2FzH4Ch3lu8p6ohMpkqRvKw8LfBdY6r6SoS2sdzRjsvaU6UCP5GZUdcs%2Bb3Vi%2FBr4%2FY15gGHOIBKuRZL7%2Fp0hwRf3%2Fo4Jc5czTWrNEZXUQtUr7AQ2vzl1kazay0m0TTMHNtj5VR8Xr7IiDd3zDuPKI8wmA1uNlmrFjsgZjnBmiBIZBosFNfIjpXE7T2iyGnBSvSJSMbr4LGrzf0BAyNcT0caIb088JSmDbPJTZVLQ2zPNIpQANQDEv2e7GS4%2FUCscI6amQNs9kRvTDH6l%2BRPgDuiYibXSvjlhpFodfLxnKQzShOK4%2B8xCCtOJGHzYXw%3D%3D HTTPSConnectionPool(host='storage.googleapis.com', port=443): Max retries exceeded with url: /wandb-production.appspot.com/runnphoenix/Flatland-flatland-multi-agent/1lwizexr/config.yaml?Expires=1643386352&GoogleAccessId=wandb-production%40appspot.gserviceaccount.com&Signature=d0Q6tcfGDB8GV%2Bv2A1Fijdoz%2FzH4Ch3lu8p6ohMpkqRvKw8LfBdY6r6SoS2sdzRjsvaU6UCP5GZUdcs%2Bb3Vi%2FBr4%2FY15gGHOIBKuRZL7%2Fp0hwRf3%2Fo4Jc5czTWrNEZXUQtUr7AQ2vzl1kazay0m0TTMHNtj5VR8Xr7IiDd3zDuPKI8wmA1uNlmrFjsgZjnBmiBIZBosFNfIjpXE7T2iyGnBSvSJSMbr4LGrzf0BAyNcT0caIb088JSmDbPJTZVLQ2zPNIpQANQDEv2e7GS4%2FUCscI6amQNs9kRvTDH6l%2BRPgDuiYibXSvjlhpFodfLxnKQzShOK4%2B8xCCtOJGHzYXw%3D%3D (Caused by ProxyError('Cannot connect to proxy.', OSError(0, 'Error')))
2022-01-28 00:13:31,408 WARNING FileStreamThread:1362264 [file_stream.py:request_with_retry():461] requests_with_retry encountered retryable exception: HTTPSConnectionPool(host='api.wandb.ai', port=443): Max retries exceeded with url: /files/runnphoenix/Flatland-flatland-multi-agent/1lwizexr/file_stream (Caused by ProxyError('Cannot connect to proxy.', OSError(0, 'Error'))). func: <bound method Session.post of <requests.sessions.Session object at 0x7fcaccb7cb80>>, args: ('https://api.wandb.ai/files/runnphoenix/Flatland-flatland-multi-agent/1lwizexr/file_stream',), kwargs: {'json': {'complete': False, 'failed': False, 'dropped': 0, 'uploaded': []}}
2022-01-28 00:14:02,480 ERROR   Thread-10 :1362264 [internal_api.py:upload_file():1546] upload_file exception https://storage.googleapis.com/wandb-production.appspot.com/runnphoenix/Flatland-flatland-multi-agent/1lwizexr/config.yaml?Expires=1643386352&GoogleAccessId=wandb-production%40appspot.gserviceaccount.com&Signature=d0Q6tcfGDB8GV%2Bv2A1Fijdoz%2FzH4Ch3lu8p6ohMpkqRvKw8LfBdY6r6SoS2sdzRjsvaU6UCP5GZUdcs%2Bb3Vi%2FBr4%2FY15gGHOIBKuRZL7%2Fp0hwRf3%2Fo4Jc5czTWrNEZXUQtUr7AQ2vzl1kazay0m0TTMHNtj5VR8Xr7IiDd3zDuPKI8wmA1uNlmrFjsgZjnBmiBIZBosFNfIjpXE7T2iyGnBSvSJSMbr4LGrzf0BAyNcT0caIb088JSmDbPJTZVLQ2zPNIpQANQDEv2e7GS4%2FUCscI6amQNs9kRvTDH6l%2BRPgDuiYibXSvjlhpFodfLxnKQzShOK4%2B8xCCtOJGHzYXw%3D%3D HTTPSConnectionPool(host='storage.googleapis.com', port=443): Max retries exceeded with url: /wandb-production.appspot.com/runnphoenix/Flatland-flatland-multi-agent/1lwizexr/config.yaml?Expires=1643386352&GoogleAccessId=wandb-production%40appspot.gserviceaccount.com&Signature=d0Q6tcfGDB8GV%2Bv2A1Fijdoz%2FzH4Ch3lu8p6ohMpkqRvKw8LfBdY6r6SoS2sdzRjsvaU6UCP5GZUdcs%2Bb3Vi%2FBr4%2FY15gGHOIBKuRZL7%2Fp0hwRf3%2Fo4Jc5czTWrNEZXUQtUr7AQ2vzl1kazay0m0TTMHNtj5VR8Xr7IiDd3zDuPKI8wmA1uNlmrFjsgZjnBmiBIZBosFNfIjpXE7T2iyGnBSvSJSMbr4LGrzf0BAyNcT0caIb088JSmDbPJTZVLQ2zPNIpQANQDEv2e7GS4%2FUCscI6amQNs9kRvTDH6l%2BRPgDuiYibXSvjlhpFodfLxnKQzShOK4%2B8xCCtOJGHzYXw%3D%3D (Caused by ProxyError('Cannot connect to proxy.', OSError(0, 'Error')))
2022-01-28 00:14:10,683 WARNING FileStreamThread:1362264 [file_stream.py:request_with_retry():461] requests_with_retry encountered retryable exception: HTTPSConnectionPool(host='api.wandb.ai', port=443): Max retries exceeded with url: /files/runnphoenix/Flatland-flatland-multi-agent/1lwizexr/file_stream (Caused by ProxyError('Cannot connect to proxy.', OSError(0, 'Error'))). func: <bound method Session.post of <requests.sessions.Session object at 0x7fcaccb7cb80>>, args: ('https://api.wandb.ai/files/runnphoenix/Flatland-flatland-multi-agent/1lwizexr/file_stream',), kwargs: {'json': {'complete': False, 'failed': False, 'dropped': 0, 'uploaded': []}}
2022-01-28 00:15:21,278 ERROR   Thread-10 :1362264 [internal_api.py:upload_file():1546] upload_file exception https://storage.googleapis.com/wandb-production.appspot.com/runnphoenix/Flatland-flatland-multi-agent/1lwizexr/config.yaml?Expires=1643386352&GoogleAccessId=wandb-production%40appspot.gserviceaccount.com&Signature=d0Q6tcfGDB8GV%2Bv2A1Fijdoz%2FzH4Ch3lu8p6ohMpkqRvKw8LfBdY6r6SoS2sdzRjsvaU6UCP5GZUdcs%2Bb3Vi%2FBr4%2FY15gGHOIBKuRZL7%2Fp0hwRf3%2Fo4Jc5czTWrNEZXUQtUr7AQ2vzl1kazay0m0TTMHNtj5VR8Xr7IiDd3zDuPKI8wmA1uNlmrFjsgZjnBmiBIZBosFNfIjpXE7T2iyGnBSvSJSMbr4LGrzf0BAyNcT0caIb088JSmDbPJTZVLQ2zPNIpQANQDEv2e7GS4%2FUCscI6amQNs9kRvTDH6l%2BRPgDuiYibXSvjlhpFodfLxnKQzShOK4%2B8xCCtOJGHzYXw%3D%3D HTTPSConnectionPool(host='storage.googleapis.com', port=443): Max retries exceeded with url: /wandb-production.appspot.com/runnphoenix/Flatland-flatland-multi-agent/1lwizexr/config.yaml?Expires=1643386352&GoogleAccessId=wandb-production%40appspot.gserviceaccount.com&Signature=d0Q6tcfGDB8GV%2Bv2A1Fijdoz%2FzH4Ch3lu8p6ohMpkqRvKw8LfBdY6r6SoS2sdzRjsvaU6UCP5GZUdcs%2Bb3Vi%2FBr4%2FY15gGHOIBKuRZL7%2Fp0hwRf3%2Fo4Jc5czTWrNEZXUQtUr7AQ2vzl1kazay0m0TTMHNtj5VR8Xr7IiDd3zDuPKI8wmA1uNlmrFjsgZjnBmiBIZBosFNfIjpXE7T2iyGnBSvSJSMbr4LGrzf0BAyNcT0caIb088JSmDbPJTZVLQ2zPNIpQANQDEv2e7GS4%2FUCscI6amQNs9kRvTDH6l%2BRPgDuiYibXSvjlhpFodfLxnKQzShOK4%2B8xCCtOJGHzYXw%3D%3D (Caused by ProxyError('Cannot connect to proxy.', OSError(0, 'Error')))
2022-01-28 00:15:22,474 WARNING FileStreamThread:1362264 [file_stream.py:request_with_retry():461] requests_with_retry encountered retryable exception: HTTPSConnectionPool(host='api.wandb.ai', port=443): Max retries exceeded with url: /files/runnphoenix/Flatland-flatland-multi-agent/1lwizexr/file_stream (Caused by ProxyError('Cannot connect to proxy.', OSError(0, 'Error'))). func: <bound method Session.post of <requests.sessions.Session object at 0x7fcaccb7cb80>>, args: ('https://api.wandb.ai/files/runnphoenix/Flatland-flatland-multi-agent/1lwizexr/file_stream',), kwargs: {'json': {'complete': False, 'failed': False, 'dropped': 0, 'uploaded': []}}
2022-01-28 00:17:46,604 INFO    MainThread:1362264 [internal.py:handle_exit():77] Internal process exited
