2022-01-26 22:35:58,927 INFO    MainThread:19655 [internal.py:wandb_internal():87] W&B internal server running at pid: 19655, started at: 2022-01-26 22:35:58.927045
2022-01-26 22:35:58,928 INFO    WriterThread:19655 [datastore.py:open_for_write():77] open: /home/runnphoenix/work/flatland-rl/rainbow/wandb/run-20220126_223557-2hjf3tae/run-2hjf3tae.wandb
2022-01-26 22:35:58,929 DEBUG   HandlerThread:19655 [handler.py:handle_request():130] handle_request: check_version
2022-01-26 22:35:58,930 DEBUG   SenderThread:19655 [sender.py:send():238] send: header
2022-01-26 22:35:58,930 DEBUG   SenderThread:19655 [sender.py:send_request():252] send_request: check_version
2022-01-26 22:36:01,947 DEBUG   SenderThread:19655 [sender.py:send():238] send: run
2022-01-26 22:36:31,947 DEBUG   HandlerThread:19655 [handler.py:handle_request():130] handle_request: shutdown
2022-01-26 22:36:31,948 INFO    HandlerThread:19655 [handler.py:finish():731] shutting down handler
2022-01-26 22:36:31,959 INFO    WriterThread:19655 [datastore.py:close():281] close: /home/runnphoenix/work/flatland-rl/rainbow/wandb/run-20220126_223557-2hjf3tae/run-2hjf3tae.wandb
2022-01-26 22:36:34,250 ERROR   SenderThread:19655 [retry.py:__call__():126] Retry attempt failed:
Traceback (most recent call last):
  File "/home/runnphoenix/anaconda3/lib/python3.8/site-packages/urllib3/connectionpool.py", line 696, in urlopen
    self._prepare_proxy(conn)
  File "/home/runnphoenix/anaconda3/lib/python3.8/site-packages/urllib3/connectionpool.py", line 964, in _prepare_proxy
    conn.connect()
  File "/home/runnphoenix/anaconda3/lib/python3.8/site-packages/urllib3/connection.py", line 411, in connect
    self.sock = ssl_wrap_socket(
  File "/home/runnphoenix/anaconda3/lib/python3.8/site-packages/urllib3/util/ssl_.py", line 428, in ssl_wrap_socket
    ssl_sock = _ssl_wrap_socket_impl(
  File "/home/runnphoenix/anaconda3/lib/python3.8/site-packages/urllib3/util/ssl_.py", line 472, in _ssl_wrap_socket_impl
    return ssl_context.wrap_socket(sock, server_hostname=server_hostname)
  File "/home/runnphoenix/anaconda3/lib/python3.8/ssl.py", line 500, in wrap_socket
    return self.sslsocket_class._create(
  File "/home/runnphoenix/anaconda3/lib/python3.8/ssl.py", line 1040, in _create
    self.do_handshake()
  File "/home/runnphoenix/anaconda3/lib/python3.8/ssl.py", line 1309, in do_handshake
    self._sslobj.do_handshake()
socket.timeout: _ssl.c:1106: The handshake operation timed out

During handling of the above exception, another exception occurred:

Traceback (most recent call last):
  File "/home/runnphoenix/anaconda3/lib/python3.8/site-packages/requests/adapters.py", line 439, in send
    resp = conn.urlopen(
  File "/home/runnphoenix/anaconda3/lib/python3.8/site-packages/urllib3/connectionpool.py", line 755, in urlopen
    retries = retries.increment(
  File "/home/runnphoenix/anaconda3/lib/python3.8/site-packages/urllib3/util/retry.py", line 573, in increment
    raise MaxRetryError(_pool, url, error or ResponseError(cause))
urllib3.exceptions.MaxRetryError: HTTPSConnectionPool(host='api.wandb.ai', port=443): Max retries exceeded with url: /graphql (Caused by ProxyError('Cannot connect to proxy.', timeout('_ssl.c:1106: The handshake operation timed out')))

During handling of the above exception, another exception occurred:

Traceback (most recent call last):
  File "/home/runnphoenix/anaconda3/lib/python3.8/site-packages/wandb/sdk/lib/retry.py", line 102, in __call__
    result = self._call_fn(*args, **kwargs)
  File "/home/runnphoenix/anaconda3/lib/python3.8/site-packages/wandb/sdk/internal/internal_api.py", line 141, in execute
    return self.client.execute(*args, **kwargs)
  File "/home/runnphoenix/anaconda3/lib/python3.8/site-packages/wandb/vendor/gql-0.2.0/gql/client.py", line 52, in execute
    result = self._get_result(document, *args, **kwargs)
  File "/home/runnphoenix/anaconda3/lib/python3.8/site-packages/wandb/vendor/gql-0.2.0/gql/client.py", line 60, in _get_result
    return self.transport.execute(document, *args, **kwargs)
  File "/home/runnphoenix/anaconda3/lib/python3.8/site-packages/wandb/vendor/gql-0.2.0/gql/transport/requests.py", line 38, in execute
    request = requests.post(self.url, **post_args)
  File "/home/runnphoenix/anaconda3/lib/python3.8/site-packages/requests/api.py", line 119, in post
    return request('post', url, data=data, json=json, **kwargs)
  File "/home/runnphoenix/anaconda3/lib/python3.8/site-packages/requests/api.py", line 61, in request
    return session.request(method=method, url=url, **kwargs)
  File "/home/runnphoenix/anaconda3/lib/python3.8/site-packages/requests/sessions.py", line 542, in request
    resp = self.send(prep, **send_kwargs)
  File "/home/runnphoenix/anaconda3/lib/python3.8/site-packages/requests/sessions.py", line 655, in send
    r = adapter.send(request, **kwargs)
  File "/home/runnphoenix/anaconda3/lib/python3.8/site-packages/requests/adapters.py", line 510, in send
    raise ProxyError(e, request=request)
requests.exceptions.ProxyError: HTTPSConnectionPool(host='api.wandb.ai', port=443): Max retries exceeded with url: /graphql (Caused by ProxyError('Cannot connect to proxy.', timeout('_ssl.c:1106: The handshake operation timed out')))
2022-01-26 22:36:56,447 INFO    SenderThread:19655 [dir_watcher.py:__init__():169] watching files in: /home/runnphoenix/work/flatland-rl/rainbow/wandb/run-20220126_223557-2hjf3tae/files
2022-01-26 22:36:56,447 INFO    SenderThread:19655 [sender.py:_start_run_threads():825] run started: 2hjf3tae with start time 1643207757
2022-01-26 22:36:56,447 INFO    SenderThread:19655 [sender.py:finish():1091] shutting down sender
2022-01-26 22:36:56,447 INFO    SenderThread:19655 [dir_watcher.py:finish():283] shutting down directory watcher
2022-01-26 22:36:57,448 INFO    SenderThread:19655 [dir_watcher.py:finish():313] scan: /home/runnphoenix/work/flatland-rl/rainbow/wandb/run-20220126_223557-2hjf3tae/files
2022-01-26 22:36:57,448 INFO    SenderThread:19655 [dir_watcher.py:finish():327] scan save: /home/runnphoenix/work/flatland-rl/rainbow/wandb/run-20220126_223557-2hjf3tae/files/config.yaml config.yaml
2022-01-26 22:36:57,448 INFO    SenderThread:19655 [file_pusher.py:finish():177] shutting down file pusher
2022-01-26 22:36:57,448 INFO    SenderThread:19655 [file_pusher.py:join():182] waiting for file pusher
2022-01-26 22:36:59,515 INFO    Thread-10 :19655 [upload_job.py:push():137] Uploaded file /home/runnphoenix/work/flatland-rl/rainbow/wandb/run-20220126_223557-2hjf3tae/files/config.yaml
2022-01-26 22:37:01,256 INFO    MainThread:19655 [internal.py:handle_exit():77] Internal process exited
