2022-01-10 00:31:52,056 INFO    MainThread:113852 [wandb_setup.py:_flush():71] setting env: {}
2022-01-10 00:31:52,056 INFO    MainThread:113852 [wandb_setup.py:_flush():71] setting login settings: {}
2022-01-10 00:31:52,056 INFO    MainThread:113852 [wandb_init.py:_log_setup():357] Logging user logs to /home/runnphoenix/work/flatland-rl/rainbow/wandb/run-20220110_003152-1ywmowlo/logs/debug.log
2022-01-10 00:31:52,056 INFO    MainThread:113852 [wandb_init.py:_log_setup():358] Logging internal logs to /home/runnphoenix/work/flatland-rl/rainbow/wandb/run-20220110_003152-1ywmowlo/logs/debug-internal.log
2022-01-10 00:31:52,056 INFO    MainThread:113852 [wandb_init.py:init():390] calling init triggers
2022-01-10 00:31:52,056 INFO    MainThread:113852 [wandb_init.py:init():395] wandb.init called with sweep_config: {}
config: {'width': 25, 'height': 25, 'num_agents': 1, 'max_num_cities': 2, 'seed': 1, 'grid_mode': False, 'max_rails_between_cities': 2, 'max_rails_in_city': 4, 'malfunction_rate': 0, 'min_duration': 20, 'max_duration': 50, 'observation_builder': 'GraphObsForRailEnv', 'predictor': 'ShortestPathPredictorForRailEnv', 'view_semiwidth': 7, 'view_height': 30, 'offset': 25, 'observation_depth': 3, 'num_episodes': 200, 'start_epoch': 0, 'max_steps': 300, 'eps': 1, 'debug_print': False, 'load_memory': False, 'evaluation_episodes': 3, 'render': False, 'evaluation_interval': 10, 'save_model_interval': 50, 'start_lr_decay': 150, 'eps_decay': 0.99, 'learning_rate': 0.02, 'learning_rate_decay': 0.1, 'learning_rate_decay_policy': 0.1, 'run_title': '3-neighbors-and-self', 'wandb_project_name': 'multi-agent-initial', 'model_path': 'test_results/', 'model_name': '', 'gat_layers': 3, 'flow': 'source_to_target', 'resume_weights': True, 'batch_norm': False, 'dropout_rate': 0.8, 'attention_heads': 4, 'batch_size': 128, 'use_stop_action': False, 'done_reward': 0, 'deadlock_reward': -10, 'reward_scaling': 0.1}
2022-01-10 00:31:52,056 INFO    MainThread:113852 [wandb_init.py:init():435] starting backend
2022-01-10 00:31:52,056 INFO    MainThread:113852 [backend.py:_multiprocessing_setup():95] multiprocessing start_methods=fork,spawn,forkserver, using: spawn
2022-01-10 00:31:52,068 INFO    MainThread:113852 [backend.py:ensure_launched():199] starting backend process...
2022-01-10 00:31:52,078 INFO    MainThread:113852 [backend.py:ensure_launched():204] started backend process with pid: 114017
2022-01-10 00:31:52,080 INFO    MainThread:113852 [wandb_init.py:init():444] backend started and connected
2022-01-10 00:31:52,082 INFO    MainThread:113852 [wandb_init.py:init():503] updated telemetry
2022-01-10 00:31:52,106 INFO    MainThread:113852 [wandb_init.py:init():533] communicating current version
2022-01-10 00:31:54,565 INFO    MainThread:113852 [wandb_init.py:init():538] got version response upgrade_message: "wandb version 0.12.9 is available!  To upgrade, please run:\n $ pip install wandb --upgrade"

2022-01-10 00:31:54,566 INFO    MainThread:113852 [wandb_init.py:init():548] communicating run to backend with 30 second timeout
2022-01-10 00:32:24,567 INFO    MainThread:113852 [interface_queue.py:_communicate_run():336] couldn't get run from backend
2022-01-10 00:32:24,567 ERROR   MainThread:113852 [wandb_init.py:init():553] backend process timed out
2022-01-10 00:32:24,567 ERROR   MainThread:113852 [wandb_init.py:init():562] encountered error: Error communicating with wandb process
try: wandb.init(settings=wandb.Settings(start_method='fork'))
or:  wandb.init(settings=wandb.Settings(start_method='thread'))
For more info see: https://docs.wandb.ai/library/init#init-start-error
2022-01-10 00:32:28,345 ERROR   Thread-1  :113852 [retry.py:__call__():126] Retry attempt failed:
Traceback (most recent call last):
  File "/home/runnphoenix/anaconda3/lib/python3.8/site-packages/urllib3/connectionpool.py", line 445, in _make_request
    six.raise_from(e, None)
  File "<string>", line 3, in raise_from
  File "/home/runnphoenix/anaconda3/lib/python3.8/site-packages/urllib3/connectionpool.py", line 440, in _make_request
    httplib_response = conn.getresponse()
  File "/home/runnphoenix/anaconda3/lib/python3.8/http/client.py", line 1347, in getresponse
    response.begin()
  File "/home/runnphoenix/anaconda3/lib/python3.8/http/client.py", line 307, in begin
    version, status, reason = self._read_status()
  File "/home/runnphoenix/anaconda3/lib/python3.8/http/client.py", line 268, in _read_status
    line = str(self.fp.readline(_MAXLINE + 1), "iso-8859-1")
  File "/home/runnphoenix/anaconda3/lib/python3.8/socket.py", line 669, in readinto
    return self._sock.recv_into(b)
  File "/home/runnphoenix/anaconda3/lib/python3.8/ssl.py", line 1241, in recv_into
    return self.read(nbytes, buffer)
  File "/home/runnphoenix/anaconda3/lib/python3.8/ssl.py", line 1099, in read
    return self._sslobj.read(len, buffer)
socket.timeout: The read operation timed out

During handling of the above exception, another exception occurred:

Traceback (most recent call last):
  File "/home/runnphoenix/anaconda3/lib/python3.8/site-packages/requests/adapters.py", line 439, in send
    resp = conn.urlopen(
  File "/home/runnphoenix/anaconda3/lib/python3.8/site-packages/urllib3/connectionpool.py", line 755, in urlopen
    retries = retries.increment(
  File "/home/runnphoenix/anaconda3/lib/python3.8/site-packages/urllib3/util/retry.py", line 531, in increment
    raise six.reraise(type(error), error, _stacktrace)
  File "/home/runnphoenix/anaconda3/lib/python3.8/site-packages/urllib3/packages/six.py", line 735, in reraise
    raise value
  File "/home/runnphoenix/anaconda3/lib/python3.8/site-packages/urllib3/connectionpool.py", line 699, in urlopen
    httplib_response = self._make_request(
  File "/home/runnphoenix/anaconda3/lib/python3.8/site-packages/urllib3/connectionpool.py", line 447, in _make_request
    self._raise_timeout(err=e, url=url, timeout_value=read_timeout)
  File "/home/runnphoenix/anaconda3/lib/python3.8/site-packages/urllib3/connectionpool.py", line 336, in _raise_timeout
    raise ReadTimeoutError(
urllib3.exceptions.ReadTimeoutError: HTTPSConnectionPool(host='api.wandb.ai', port=443): Read timed out. (read timeout=10)

During handling of the above exception, another exception occurred:

Traceback (most recent call last):
  File "/home/runnphoenix/anaconda3/lib/python3.8/site-packages/wandb/sdk/lib/retry.py", line 102, in __call__
    result = self._call_fn(*args, **kwargs)
  File "/home/runnphoenix/anaconda3/lib/python3.8/site-packages/wandb/sdk/internal/internal_api.py", line 141, in execute
    return self.client.execute(*args, **kwargs)
  File "/home/runnphoenix/anaconda3/lib/python3.8/site-packages/wandb/vendor/gql-0.2.0/gql/client.py", line 52, in execute
    result = self._get_result(document, *args, **kwargs)
  File "/home/runnphoenix/anaconda3/lib/python3.8/site-packages/wandb/vendor/gql-0.2.0/gql/client.py", line 60, in _get_result
    return self.transport.execute(document, *args, **kwargs)
  File "/home/runnphoenix/anaconda3/lib/python3.8/site-packages/wandb/vendor/gql-0.2.0/gql/transport/requests.py", line 38, in execute
    request = requests.post(self.url, **post_args)
  File "/home/runnphoenix/anaconda3/lib/python3.8/site-packages/requests/api.py", line 119, in post
    return request('post', url, data=data, json=json, **kwargs)
  File "/home/runnphoenix/anaconda3/lib/python3.8/site-packages/requests/api.py", line 61, in request
    return session.request(method=method, url=url, **kwargs)
  File "/home/runnphoenix/anaconda3/lib/python3.8/site-packages/requests/sessions.py", line 542, in request
    resp = self.send(prep, **send_kwargs)
  File "/home/runnphoenix/anaconda3/lib/python3.8/site-packages/requests/sessions.py", line 655, in send
    r = adapter.send(request, **kwargs)
  File "/home/runnphoenix/anaconda3/lib/python3.8/site-packages/requests/adapters.py", line 529, in send
    raise ReadTimeout(e, request=request)
requests.exceptions.ReadTimeout: HTTPSConnectionPool(host='api.wandb.ai', port=443): Read timed out. (read timeout=10)
2022-01-10 00:33:20,996 INFO    MainThread:113852 [wandb_init.py:teardown():205] tearing down wandb.init
