2022-01-02 23:09:04,666 INFO    MainThread:49385 [wandb_setup.py:_flush():71] setting env: {}
2022-01-02 23:09:04,666 INFO    MainThread:49385 [wandb_setup.py:_flush():71] setting login settings: {}
2022-01-02 23:09:04,666 INFO    MainThread:49385 [wandb_init.py:_log_setup():357] Logging user logs to /home/runnphoenix/work/flatland-rl/rainbow/wandb/run-20220102_230904-2tle7vrb/logs/debug.log
2022-01-02 23:09:04,666 INFO    MainThread:49385 [wandb_init.py:_log_setup():358] Logging internal logs to /home/runnphoenix/work/flatland-rl/rainbow/wandb/run-20220102_230904-2tle7vrb/logs/debug-internal.log
2022-01-02 23:09:04,666 INFO    MainThread:49385 [wandb_init.py:init():390] calling init triggers
2022-01-02 23:09:04,666 INFO    MainThread:49385 [wandb_init.py:init():395] wandb.init called with sweep_config: {}
config: {'width': 25, 'height': 25, 'num_agents': 1, 'max_num_cities': 2, 'seed': 1, 'grid_mode': False, 'max_rails_between_cities': 2, 'max_rails_in_city': 4, 'malfunction_rate': 0, 'min_duration': 20, 'max_duration': 50, 'observation_builder': 'GraphObsForRailEnv', 'predictor': 'ShortestPathPredictorForRailEnv', 'view_semiwidth': 7, 'view_height': 30, 'offset': 25, 'observation_depth': 3, 'num_episodes': 200, 'start_epoch': 0, 'max_steps': 300, 'eps': 1, 'debug_print': False, 'load_memory': False, 'evaluation_episodes': 3, 'render': False, 'evaluation_interval': 10, 'save_model_interval': 50, 'start_lr_decay': 150, 'eps_decay': 0.999, 'learning_rate': 0.02, 'learning_rate_decay': 0.5, 'learning_rate_decay_policy': 0.5, 'run_title': 'first_run', 'wandb_project_name': 'wandb_default', 'model_path': 'test_results/', 'model_name': '', 'gat_layers': 3, 'flow': 'source_to_target', 'resume_weights': True, 'batch_norm': False, 'dropout_rate': 0.8, 'attention_heads': 4, 'batch_size': 128, 'use_stop_action': False, 'done_reward': 0, 'deadlock_reward': -1000, 'reward_scaling': 0.1}
2022-01-02 23:09:04,666 INFO    MainThread:49385 [wandb_init.py:init():435] starting backend
2022-01-02 23:09:04,666 INFO    MainThread:49385 [backend.py:_multiprocessing_setup():95] multiprocessing start_methods=fork,spawn,forkserver, using: spawn
2022-01-02 23:09:04,679 INFO    MainThread:49385 [backend.py:ensure_launched():199] starting backend process...
2022-01-02 23:09:04,688 INFO    MainThread:49385 [backend.py:ensure_launched():204] started backend process with pid: 49505
2022-01-02 23:09:04,690 INFO    MainThread:49385 [wandb_init.py:init():444] backend started and connected
2022-01-02 23:09:04,692 INFO    MainThread:49385 [wandb_init.py:init():503] updated telemetry
2022-01-02 23:09:04,716 INFO    MainThread:49385 [wandb_init.py:init():533] communicating current version
2022-01-02 23:09:08,662 INFO    MainThread:49385 [wandb_init.py:init():538] got version response 
2022-01-02 23:09:08,662 INFO    MainThread:49385 [wandb_init.py:init():548] communicating run to backend with 30 second timeout
2022-01-02 23:09:27,096 INFO    MainThread:49385 [wandb_init.py:init():576] starting run threads in backend
2022-01-02 23:09:30,465 ERROR   Thread-1  :49385 [retry.py:__call__():126] Retry attempt failed:
Traceback (most recent call last):
  File "/home/runnphoenix/anaconda3/lib/python3.8/site-packages/urllib3/connectionpool.py", line 696, in urlopen
    self._prepare_proxy(conn)
  File "/home/runnphoenix/anaconda3/lib/python3.8/site-packages/urllib3/connectionpool.py", line 964, in _prepare_proxy
    conn.connect()
  File "/home/runnphoenix/anaconda3/lib/python3.8/site-packages/urllib3/connection.py", line 411, in connect
    self.sock = ssl_wrap_socket(
  File "/home/runnphoenix/anaconda3/lib/python3.8/site-packages/urllib3/util/ssl_.py", line 428, in ssl_wrap_socket
    ssl_sock = _ssl_wrap_socket_impl(
  File "/home/runnphoenix/anaconda3/lib/python3.8/site-packages/urllib3/util/ssl_.py", line 472, in _ssl_wrap_socket_impl
    return ssl_context.wrap_socket(sock, server_hostname=server_hostname)
  File "/home/runnphoenix/anaconda3/lib/python3.8/ssl.py", line 500, in wrap_socket
    return self.sslsocket_class._create(
  File "/home/runnphoenix/anaconda3/lib/python3.8/ssl.py", line 1040, in _create
    self.do_handshake()
  File "/home/runnphoenix/anaconda3/lib/python3.8/ssl.py", line 1309, in do_handshake
    self._sslobj.do_handshake()
OSError: [Errno 0] Error

During handling of the above exception, another exception occurred:

Traceback (most recent call last):
  File "/home/runnphoenix/anaconda3/lib/python3.8/site-packages/requests/adapters.py", line 439, in send
    resp = conn.urlopen(
  File "/home/runnphoenix/anaconda3/lib/python3.8/site-packages/urllib3/connectionpool.py", line 755, in urlopen
    retries = retries.increment(
  File "/home/runnphoenix/anaconda3/lib/python3.8/site-packages/urllib3/util/retry.py", line 573, in increment
    raise MaxRetryError(_pool, url, error or ResponseError(cause))
urllib3.exceptions.MaxRetryError: HTTPSConnectionPool(host='api.wandb.ai', port=443): Max retries exceeded with url: /graphql (Caused by ProxyError('Cannot connect to proxy.', OSError(0, 'Error')))

During handling of the above exception, another exception occurred:

Traceback (most recent call last):
  File "/home/runnphoenix/anaconda3/lib/python3.8/site-packages/wandb/sdk/lib/retry.py", line 102, in __call__
    result = self._call_fn(*args, **kwargs)
  File "/home/runnphoenix/anaconda3/lib/python3.8/site-packages/wandb/sdk/internal/internal_api.py", line 141, in execute
    return self.client.execute(*args, **kwargs)
  File "/home/runnphoenix/anaconda3/lib/python3.8/site-packages/wandb/vendor/gql-0.2.0/gql/client.py", line 52, in execute
    result = self._get_result(document, *args, **kwargs)
  File "/home/runnphoenix/anaconda3/lib/python3.8/site-packages/wandb/vendor/gql-0.2.0/gql/client.py", line 60, in _get_result
    return self.transport.execute(document, *args, **kwargs)
  File "/home/runnphoenix/anaconda3/lib/python3.8/site-packages/wandb/vendor/gql-0.2.0/gql/transport/requests.py", line 38, in execute
    request = requests.post(self.url, **post_args)
  File "/home/runnphoenix/anaconda3/lib/python3.8/site-packages/requests/api.py", line 119, in post
    return request('post', url, data=data, json=json, **kwargs)
  File "/home/runnphoenix/anaconda3/lib/python3.8/site-packages/requests/api.py", line 61, in request
    return session.request(method=method, url=url, **kwargs)
  File "/home/runnphoenix/anaconda3/lib/python3.8/site-packages/requests/sessions.py", line 542, in request
    resp = self.send(prep, **send_kwargs)
  File "/home/runnphoenix/anaconda3/lib/python3.8/site-packages/requests/sessions.py", line 655, in send
    r = adapter.send(request, **kwargs)
  File "/home/runnphoenix/anaconda3/lib/python3.8/site-packages/requests/adapters.py", line 510, in send
    raise ProxyError(e, request=request)
requests.exceptions.ProxyError: HTTPSConnectionPool(host='api.wandb.ai', port=443): Max retries exceeded with url: /graphql (Caused by ProxyError('Cannot connect to proxy.', OSError(0, 'Error')))
2022-01-02 23:09:32,099 INFO    MainThread:49385 [wandb_run.py:_console_start():1693] atexit reg
2022-01-02 23:09:32,100 INFO    MainThread:49385 [wandb_run.py:_redirect():1567] redirect: SettingsConsole.REDIRECT
2022-01-02 23:09:32,100 INFO    MainThread:49385 [wandb_run.py:_redirect():1572] Redirecting console.
2022-01-02 23:09:32,103 INFO    MainThread:49385 [wandb_run.py:_redirect():1628] Redirects installed.
2022-01-02 23:09:32,103 INFO    MainThread:49385 [wandb_init.py:init():603] run started, returning control to user process
2022-01-02 23:09:36,187 INFO    MainThread:49385 [wandb_watch.py:watch():43] Watching
2022-01-02 23:13:32,454 INFO    MainThread:49385 [wandb_run.py:_atexit_cleanup():1663] got exitcode: 255
2022-01-02 23:13:32,456 INFO    MainThread:49385 [wandb_run.py:_restore():1635] restore
