2022-01-02 23:13:47,490 INFO    MainThread:53838 [internal.py:wandb_internal():87] W&B internal server running at pid: 53838, started at: 2022-01-02 23:13:47.490276
2022-01-02 23:13:47,492 INFO    WriterThread:53838 [datastore.py:open_for_write():77] open: /home/runnphoenix/work/flatland-rl/rainbow/wandb/run-20220102_231346-3a9bxb0q/run-3a9bxb0q.wandb
2022-01-02 23:13:47,492 DEBUG   HandlerThread:53838 [handler.py:handle_request():130] handle_request: check_version
2022-01-02 23:13:47,493 DEBUG   SenderThread:53838 [sender.py:send():238] send: header
2022-01-02 23:13:47,493 DEBUG   SenderThread:53838 [sender.py:send_request():252] send_request: check_version
2022-01-02 23:13:50,511 DEBUG   SenderThread:53838 [sender.py:send():238] send: run
2022-01-02 23:13:53,939 INFO    SenderThread:53838 [dir_watcher.py:__init__():169] watching files in: /home/runnphoenix/work/flatland-rl/rainbow/wandb/run-20220102_231346-3a9bxb0q/files
2022-01-02 23:13:53,939 INFO    SenderThread:53838 [sender.py:_start_run_threads():825] run started: 3a9bxb0q with start time 1641136426
2022-01-02 23:13:53,939 DEBUG   SenderThread:53838 [sender.py:send():238] send: summary
2022-01-02 23:13:53,940 INFO    SenderThread:53838 [sender.py:_save_file():960] saving file wandb-summary.json with policy end
2022-01-02 23:13:53,941 DEBUG   HandlerThread:53838 [handler.py:handle_request():130] handle_request: run_start
2022-01-02 23:13:53,944 DEBUG   HandlerThread:53838 [meta.py:__init__():40] meta init
2022-01-02 23:13:53,944 DEBUG   HandlerThread:53838 [meta.py:__init__():54] meta init done
2022-01-02 23:13:53,944 DEBUG   HandlerThread:53838 [meta.py:probe():214] probe
2022-01-02 23:13:53,951 DEBUG   HandlerThread:53838 [meta.py:_setup_git():204] setup git
2022-01-02 23:13:53,964 DEBUG   HandlerThread:53838 [meta.py:_setup_git():211] setup git done
2022-01-02 23:13:53,964 DEBUG   HandlerThread:53838 [meta.py:_save_pip():58] save pip
2022-01-02 23:13:53,965 DEBUG   HandlerThread:53838 [meta.py:_save_pip():72] save pip done
2022-01-02 23:13:53,965 DEBUG   HandlerThread:53838 [meta.py:_save_conda():79] save conda
2022-01-02 23:13:54,941 INFO    Thread-8  :53838 [dir_watcher.py:_on_file_created():217] file/dir created: /home/runnphoenix/work/flatland-rl/rainbow/wandb/run-20220102_231346-3a9bxb0q/files/requirements.txt
2022-01-02 23:13:54,941 INFO    Thread-8  :53838 [dir_watcher.py:_on_file_created():217] file/dir created: /home/runnphoenix/work/flatland-rl/rainbow/wandb/run-20220102_231346-3a9bxb0q/files/wandb-summary.json
2022-01-02 23:13:54,941 INFO    Thread-8  :53838 [dir_watcher.py:_on_file_created():217] file/dir created: /home/runnphoenix/work/flatland-rl/rainbow/wandb/run-20220102_231346-3a9bxb0q/files/conda-environment.yaml
2022-01-02 23:13:59,944 INFO    Thread-8  :53838 [dir_watcher.py:_on_file_created():217] file/dir created: /home/runnphoenix/work/flatland-rl/rainbow/wandb/run-20220102_231346-3a9bxb0q/files/output.log
2022-01-02 23:14:01,944 INFO    Thread-8  :53838 [dir_watcher.py:_on_file_modified():230] file/dir modified: /home/runnphoenix/work/flatland-rl/rainbow/wandb/run-20220102_231346-3a9bxb0q/files/output.log
2022-01-02 23:14:03,945 INFO    Thread-8  :53838 [dir_watcher.py:_on_file_modified():230] file/dir modified: /home/runnphoenix/work/flatland-rl/rainbow/wandb/run-20220102_231346-3a9bxb0q/files/output.log
2022-01-02 23:14:07,553 WARNING FileStreamThread:53838 [file_stream.py:request_with_retry():461] requests_with_retry encountered retryable exception: HTTPSConnectionPool(host='api.wandb.ai', port=443): Max retries exceeded with url: /files/runnphoenix/Flatland-wandb_default/3a9bxb0q/file_stream (Caused by ProxyError('Cannot connect to proxy.', OSError(0, 'Error'))). func: <bound method Session.post of <requests.sessions.Session object at 0x7ff7e3114c70>>, args: ('https://api.wandb.ai/files/runnphoenix/Flatland-wandb_default/3a9bxb0q/file_stream',), kwargs: {'json': {'files': {'wandb-summary.json': {'offset': 0, 'content': ['{}']}}, 'dropped': 0}}
2022-01-02 23:14:07,740 DEBUG   HandlerThread:53838 [meta.py:_save_conda():89] save conda done
2022-01-02 23:14:07,740 DEBUG   HandlerThread:53838 [meta.py:probe():252] probe done
2022-01-02 23:14:07,895 DEBUG   HandlerThread:53838 [handler.py:handle_request():130] handle_request: stop_status
2022-01-02 23:14:07,895 DEBUG   SenderThread:53838 [sender.py:send_request():252] send_request: stop_status
2022-01-02 23:14:07,946 INFO    Thread-8  :53838 [dir_watcher.py:_on_file_modified():230] file/dir modified: /home/runnphoenix/work/flatland-rl/rainbow/wandb/run-20220102_231346-3a9bxb0q/files/conda-environment.yaml
2022-01-02 23:14:07,946 INFO    Thread-8  :53838 [dir_watcher.py:_on_file_created():217] file/dir created: /home/runnphoenix/work/flatland-rl/rainbow/wandb/run-20220102_231346-3a9bxb0q/files/wandb-metadata.json
2022-01-02 23:14:10,650 DEBUG   SenderThread:53838 [sender.py:send():238] send: files
2022-01-02 23:14:10,650 INFO    SenderThread:53838 [sender.py:_save_file():960] saving file wandb-metadata.json with policy now
2022-01-02 23:14:17,698 DEBUG   SenderThread:53838 [sender.py:send():238] send: history
2022-01-02 23:14:17,699 DEBUG   SenderThread:53838 [sender.py:send():238] send: summary
2022-01-02 23:14:17,701 INFO    SenderThread:53838 [sender.py:_save_file():960] saving file wandb-summary.json with policy end
2022-01-02 23:14:17,948 INFO    Thread-8  :53838 [dir_watcher.py:_on_file_modified():230] file/dir modified: /home/runnphoenix/work/flatland-rl/rainbow/wandb/run-20220102_231346-3a9bxb0q/files/wandb-summary.json
2022-01-02 23:14:18,944 DEBUG   HandlerThread:53838 [handler.py:handle_request():130] handle_request: stop_status
2022-01-02 23:14:18,944 DEBUG   SenderThread:53838 [sender.py:send_request():252] send_request: stop_status
2022-01-02 23:14:19,949 INFO    Thread-8  :53838 [dir_watcher.py:_on_file_modified():230] file/dir modified: /home/runnphoenix/work/flatland-rl/rainbow/wandb/run-20220102_231346-3a9bxb0q/files/output.log
2022-01-02 23:14:23,950 INFO    Thread-8  :53838 [dir_watcher.py:_on_file_modified():230] file/dir modified: /home/runnphoenix/work/flatland-rl/rainbow/wandb/run-20220102_231346-3a9bxb0q/files/output.log
2022-01-02 23:14:31,733 ERROR   Thread-11 :53838 [internal_api.py:upload_file():1546] upload_file exception https://storage.googleapis.com/wandb-production.appspot.com/runnphoenix/Flatland-wandb_default/3a9bxb0q/wandb-metadata.json?Expires=1641222858&GoogleAccessId=wandb-production%40appspot.gserviceaccount.com&Signature=lmq3VJMKzgK8YF%2BOIp6oedeVDGeWieEYBSvZae46%2BJb6UpyIVtheUJ%2FHZgvC7u0gPfvEQ7HxPwACe9%2B5bGBcNy%2FW5Bm0d0VEZhLuLvjX%2FfibkzEIMGa%2Ftf2bMCDJxlLQQLo0Oku3EmtN4E7sbw%2FiVxO2pWrzByrjN7uMhavJ%2FcGjIv7zWRROcAcPeiV1OKl%2FpIIx%2FhLG9BNB6qZK92TbL0CIFaX%2BKq6GYT4t1bUurp29AhKzB3IdJivOGUoImfdCN2GT%2FkLozmeJiiU%2BhZj9ED5du0DGmDoaiMEDOn3nyoMXg994wPjMTBvIUP9Bv5Xtp5Yu63iJTw9LlMRpCy64gg%3D%3D HTTPSConnectionPool(host='storage.googleapis.com', port=443): Max retries exceeded with url: /wandb-production.appspot.com/runnphoenix/Flatland-wandb_default/3a9bxb0q/wandb-metadata.json?Expires=1641222858&GoogleAccessId=wandb-production%40appspot.gserviceaccount.com&Signature=lmq3VJMKzgK8YF%2BOIp6oedeVDGeWieEYBSvZae46%2BJb6UpyIVtheUJ%2FHZgvC7u0gPfvEQ7HxPwACe9%2B5bGBcNy%2FW5Bm0d0VEZhLuLvjX%2FfibkzEIMGa%2Ftf2bMCDJxlLQQLo0Oku3EmtN4E7sbw%2FiVxO2pWrzByrjN7uMhavJ%2FcGjIv7zWRROcAcPeiV1OKl%2FpIIx%2FhLG9BNB6qZK92TbL0CIFaX%2BKq6GYT4t1bUurp29AhKzB3IdJivOGUoImfdCN2GT%2FkLozmeJiiU%2BhZj9ED5du0DGmDoaiMEDOn3nyoMXg994wPjMTBvIUP9Bv5Xtp5Yu63iJTw9LlMRpCy64gg%3D%3D (Caused by ProxyError('Cannot connect to proxy.', OSError(0, 'Error')))
2022-01-02 23:14:34,207 DEBUG   SenderThread:53838 [sender.py:send():238] send: stats
2022-01-02 23:14:34,209 DEBUG   SenderThread:53838 [sender.py:send():238] send: history
2022-01-02 23:14:34,210 DEBUG   SenderThread:53838 [sender.py:send():238] send: summary
2022-01-02 23:14:34,212 INFO    SenderThread:53838 [sender.py:_save_file():960] saving file wandb-summary.json with policy end
2022-01-02 23:14:34,320 INFO    Thread-11 :53838 [upload_job.py:push():137] Uploaded file /tmp/tmpr58fg5ulwandb/15qmfq21-wandb-metadata.json
2022-01-02 23:14:34,953 INFO    Thread-8  :53838 [dir_watcher.py:_on_file_modified():230] file/dir modified: /home/runnphoenix/work/flatland-rl/rainbow/wandb/run-20220102_231346-3a9bxb0q/files/wandb-summary.json
2022-01-02 23:14:38,945 DEBUG   HandlerThread:53838 [handler.py:handle_request():130] handle_request: stop_status
2022-01-02 23:14:38,945 DEBUG   SenderThread:53838 [sender.py:send_request():252] send_request: stop_status
2022-01-02 23:14:52,423 DEBUG   SenderThread:53838 [sender.py:send():238] send: stats
2022-01-02 23:14:53,607 DEBUG   SenderThread:53838 [sender.py:send():238] send: history
2022-01-02 23:14:53,609 DEBUG   SenderThread:53838 [sender.py:send():238] send: summary
2022-01-02 23:14:53,611 INFO    SenderThread:53838 [sender.py:_save_file():960] saving file wandb-summary.json with policy end
2022-01-02 23:14:53,958 INFO    Thread-8  :53838 [dir_watcher.py:_on_file_modified():230] file/dir modified: /home/runnphoenix/work/flatland-rl/rainbow/wandb/run-20220102_231346-3a9bxb0q/files/wandb-summary.json
2022-01-02 23:14:54,605 DEBUG   HandlerThread:53838 [handler.py:handle_request():130] handle_request: stop_status
2022-01-02 23:14:54,606 DEBUG   SenderThread:53838 [sender.py:send_request():252] send_request: stop_status
2022-01-02 23:14:55,959 INFO    Thread-8  :53838 [dir_watcher.py:_on_file_modified():230] file/dir modified: /home/runnphoenix/work/flatland-rl/rainbow/wandb/run-20220102_231346-3a9bxb0q/files/output.log
2022-01-02 23:15:14,606 DEBUG   HandlerThread:53838 [handler.py:handle_request():130] handle_request: stop_status
2022-01-02 23:15:23,126 DEBUG   SenderThread:53838 [sender.py:send_request():252] send_request: stop_status
2022-01-02 23:15:34,390 DEBUG   SenderThread:53838 [sender.py:send():238] send: stats
2022-01-02 23:15:34,607 DEBUG   HandlerThread:53838 [handler.py:handle_request():130] handle_request: stop_status
2022-01-02 23:15:34,607 DEBUG   SenderThread:53838 [sender.py:send_request():252] send_request: stop_status
2022-01-02 23:15:54,607 DEBUG   HandlerThread:53838 [handler.py:handle_request():130] handle_request: stop_status
2022-01-02 23:16:06,031 DEBUG   SenderThread:53838 [sender.py:send():238] send: stats
2022-01-02 23:16:06,031 DEBUG   SenderThread:53838 [sender.py:send_request():252] send_request: stop_status
2022-01-02 23:16:14,608 DEBUG   HandlerThread:53838 [handler.py:handle_request():130] handle_request: stop_status
2022-01-02 23:16:17,980 INFO    Thread-8  :53838 [dir_watcher.py:_on_file_modified():230] file/dir modified: /home/runnphoenix/work/flatland-rl/rainbow/wandb/run-20220102_231346-3a9bxb0q/files/output.log
2022-01-02 23:16:19,956 DEBUG   SenderThread:53838 [sender.py:send_request():252] send_request: stop_status
2022-01-02 23:16:22,414 DEBUG   SenderThread:53838 [sender.py:send():238] send: history
2022-01-02 23:16:22,416 DEBUG   SenderThread:53838 [sender.py:send():238] send: summary
2022-01-02 23:16:22,420 INFO    SenderThread:53838 [sender.py:_save_file():960] saving file wandb-summary.json with policy end
2022-01-02 23:16:22,982 INFO    Thread-8  :53838 [dir_watcher.py:_on_file_modified():230] file/dir modified: /home/runnphoenix/work/flatland-rl/rainbow/wandb/run-20220102_231346-3a9bxb0q/files/wandb-summary.json
2022-01-02 23:16:23,091 DEBUG   SenderThread:53838 [sender.py:send():238] send: stats
2022-01-02 23:16:34,608 DEBUG   HandlerThread:53838 [handler.py:handle_request():130] handle_request: stop_status
2022-01-02 23:16:34,608 DEBUG   SenderThread:53838 [sender.py:send_request():252] send_request: stop_status
2022-01-02 23:16:53,321 DEBUG   SenderThread:53838 [sender.py:send():238] send: stats
2022-01-02 23:16:54,609 DEBUG   HandlerThread:53838 [handler.py:handle_request():130] handle_request: stop_status
2022-01-02 23:16:54,609 DEBUG   SenderThread:53838 [sender.py:send_request():252] send_request: stop_status
2022-01-02 23:16:54,931 WARNING MainThread:53838 [internal.py:wandb_internal():146] Internal process interrupt: 1
2022-01-02 23:16:57,546 WARNING MainThread:53838 [internal.py:wandb_internal():146] Internal process interrupt: 2
2022-01-02 23:16:57,547 ERROR   MainThread:53838 [internal.py:wandb_internal():149] Internal process interrupted.
2022-01-02 23:16:57,991 INFO    Thread-8  :53838 [dir_watcher.py:_on_file_modified():230] file/dir modified: /home/runnphoenix/work/flatland-rl/rainbow/wandb/run-20220102_231346-3a9bxb0q/files/output.log
2022-01-02 23:16:58,154 INFO    WriterThread:53838 [datastore.py:close():281] close: /home/runnphoenix/work/flatland-rl/rainbow/wandb/run-20220102_231346-3a9bxb0q/run-3a9bxb0q.wandb
2022-01-02 23:16:58,155 INFO    HandlerThread:53838 [handler.py:finish():731] shutting down handler
2022-01-02 23:17:08,459 INFO    SenderThread:53838 [sender.py:finish():1091] shutting down sender
2022-01-02 23:17:08,459 INFO    SenderThread:53838 [dir_watcher.py:finish():283] shutting down directory watcher
2022-01-02 23:17:08,994 INFO    SenderThread:53838 [dir_watcher.py:finish():313] scan: /home/runnphoenix/work/flatland-rl/rainbow/wandb/run-20220102_231346-3a9bxb0q/files
2022-01-02 23:17:08,994 INFO    SenderThread:53838 [dir_watcher.py:finish():327] scan save: /home/runnphoenix/work/flatland-rl/rainbow/wandb/run-20220102_231346-3a9bxb0q/files/config.yaml config.yaml
2022-01-02 23:17:08,994 INFO    SenderThread:53838 [dir_watcher.py:finish():327] scan save: /home/runnphoenix/work/flatland-rl/rainbow/wandb/run-20220102_231346-3a9bxb0q/files/requirements.txt requirements.txt
2022-01-02 23:17:08,994 INFO    SenderThread:53838 [dir_watcher.py:finish():327] scan save: /home/runnphoenix/work/flatland-rl/rainbow/wandb/run-20220102_231346-3a9bxb0q/files/output.log output.log
2022-01-02 23:17:08,994 INFO    SenderThread:53838 [dir_watcher.py:finish():327] scan save: /home/runnphoenix/work/flatland-rl/rainbow/wandb/run-20220102_231346-3a9bxb0q/files/wandb-summary.json wandb-summary.json
2022-01-02 23:17:08,994 INFO    SenderThread:53838 [dir_watcher.py:finish():327] scan save: /home/runnphoenix/work/flatland-rl/rainbow/wandb/run-20220102_231346-3a9bxb0q/files/conda-environment.yaml conda-environment.yaml
2022-01-02 23:17:08,995 INFO    SenderThread:53838 [dir_watcher.py:finish():327] scan save: /home/runnphoenix/work/flatland-rl/rainbow/wandb/run-20220102_231346-3a9bxb0q/files/wandb-metadata.json wandb-metadata.json
2022-01-02 23:17:08,995 INFO    SenderThread:53838 [file_pusher.py:finish():177] shutting down file pusher
2022-01-02 23:17:08,995 INFO    SenderThread:53838 [file_pusher.py:join():182] waiting for file pusher
2022-01-02 23:17:24,557 ERROR   Thread-14 :53838 [retry.py:__call__():126] Retry attempt failed:
Traceback (most recent call last):
  File "/home/runnphoenix/anaconda3/lib/python3.8/site-packages/urllib3/connectionpool.py", line 696, in urlopen
    self._prepare_proxy(conn)
  File "/home/runnphoenix/anaconda3/lib/python3.8/site-packages/urllib3/connectionpool.py", line 964, in _prepare_proxy
    conn.connect()
  File "/home/runnphoenix/anaconda3/lib/python3.8/site-packages/urllib3/connection.py", line 411, in connect
    self.sock = ssl_wrap_socket(
  File "/home/runnphoenix/anaconda3/lib/python3.8/site-packages/urllib3/util/ssl_.py", line 428, in ssl_wrap_socket
    ssl_sock = _ssl_wrap_socket_impl(
  File "/home/runnphoenix/anaconda3/lib/python3.8/site-packages/urllib3/util/ssl_.py", line 472, in _ssl_wrap_socket_impl
    return ssl_context.wrap_socket(sock, server_hostname=server_hostname)
  File "/home/runnphoenix/anaconda3/lib/python3.8/ssl.py", line 500, in wrap_socket
    return self.sslsocket_class._create(
  File "/home/runnphoenix/anaconda3/lib/python3.8/ssl.py", line 1040, in _create
    self.do_handshake()
  File "/home/runnphoenix/anaconda3/lib/python3.8/ssl.py", line 1309, in do_handshake
    self._sslobj.do_handshake()
socket.timeout: _ssl.c:1106: The handshake operation timed out

During handling of the above exception, another exception occurred:

Traceback (most recent call last):
  File "/home/runnphoenix/anaconda3/lib/python3.8/site-packages/requests/adapters.py", line 439, in send
    resp = conn.urlopen(
  File "/home/runnphoenix/anaconda3/lib/python3.8/site-packages/urllib3/connectionpool.py", line 755, in urlopen
    retries = retries.increment(
  File "/home/runnphoenix/anaconda3/lib/python3.8/site-packages/urllib3/util/retry.py", line 573, in increment
    raise MaxRetryError(_pool, url, error or ResponseError(cause))
urllib3.exceptions.MaxRetryError: HTTPSConnectionPool(host='api.wandb.ai', port=443): Max retries exceeded with url: /graphql (Caused by ProxyError('Cannot connect to proxy.', timeout('_ssl.c:1106: The handshake operation timed out')))

During handling of the above exception, another exception occurred:

Traceback (most recent call last):
  File "/home/runnphoenix/anaconda3/lib/python3.8/site-packages/wandb/sdk/lib/retry.py", line 102, in __call__
    result = self._call_fn(*args, **kwargs)
  File "/home/runnphoenix/anaconda3/lib/python3.8/site-packages/wandb/sdk/internal/internal_api.py", line 141, in execute
    return self.client.execute(*args, **kwargs)
  File "/home/runnphoenix/anaconda3/lib/python3.8/site-packages/wandb/vendor/gql-0.2.0/gql/client.py", line 52, in execute
    result = self._get_result(document, *args, **kwargs)
  File "/home/runnphoenix/anaconda3/lib/python3.8/site-packages/wandb/vendor/gql-0.2.0/gql/client.py", line 60, in _get_result
    return self.transport.execute(document, *args, **kwargs)
  File "/home/runnphoenix/anaconda3/lib/python3.8/site-packages/wandb/vendor/gql-0.2.0/gql/transport/requests.py", line 38, in execute
    request = requests.post(self.url, **post_args)
  File "/home/runnphoenix/anaconda3/lib/python3.8/site-packages/requests/api.py", line 119, in post
    return request('post', url, data=data, json=json, **kwargs)
  File "/home/runnphoenix/anaconda3/lib/python3.8/site-packages/requests/api.py", line 61, in request
    return session.request(method=method, url=url, **kwargs)
  File "/home/runnphoenix/anaconda3/lib/python3.8/site-packages/requests/sessions.py", line 542, in request
    resp = self.send(prep, **send_kwargs)
  File "/home/runnphoenix/anaconda3/lib/python3.8/site-packages/requests/sessions.py", line 655, in send
    r = adapter.send(request, **kwargs)
  File "/home/runnphoenix/anaconda3/lib/python3.8/site-packages/requests/adapters.py", line 510, in send
    raise ProxyError(e, request=request)
requests.exceptions.ProxyError: HTTPSConnectionPool(host='api.wandb.ai', port=443): Max retries exceeded with url: /graphql (Caused by ProxyError('Cannot connect to proxy.', timeout('_ssl.c:1106: The handshake operation timed out')))
2022-01-02 23:17:24,771 ERROR   Thread-13 :53838 [retry.py:__call__():126] Retry attempt failed:
Traceback (most recent call last):
  File "/home/runnphoenix/anaconda3/lib/python3.8/site-packages/urllib3/connectionpool.py", line 696, in urlopen
    self._prepare_proxy(conn)
  File "/home/runnphoenix/anaconda3/lib/python3.8/site-packages/urllib3/connectionpool.py", line 964, in _prepare_proxy
    conn.connect()
  File "/home/runnphoenix/anaconda3/lib/python3.8/site-packages/urllib3/connection.py", line 411, in connect
    self.sock = ssl_wrap_socket(
  File "/home/runnphoenix/anaconda3/lib/python3.8/site-packages/urllib3/util/ssl_.py", line 428, in ssl_wrap_socket
    ssl_sock = _ssl_wrap_socket_impl(
  File "/home/runnphoenix/anaconda3/lib/python3.8/site-packages/urllib3/util/ssl_.py", line 472, in _ssl_wrap_socket_impl
    return ssl_context.wrap_socket(sock, server_hostname=server_hostname)
  File "/home/runnphoenix/anaconda3/lib/python3.8/ssl.py", line 500, in wrap_socket
    return self.sslsocket_class._create(
  File "/home/runnphoenix/anaconda3/lib/python3.8/ssl.py", line 1040, in _create
    self.do_handshake()
  File "/home/runnphoenix/anaconda3/lib/python3.8/ssl.py", line 1309, in do_handshake
    self._sslobj.do_handshake()
socket.timeout: _ssl.c:1106: The handshake operation timed out

During handling of the above exception, another exception occurred:

Traceback (most recent call last):
  File "/home/runnphoenix/anaconda3/lib/python3.8/site-packages/requests/adapters.py", line 439, in send
    resp = conn.urlopen(
  File "/home/runnphoenix/anaconda3/lib/python3.8/site-packages/urllib3/connectionpool.py", line 755, in urlopen
    retries = retries.increment(
  File "/home/runnphoenix/anaconda3/lib/python3.8/site-packages/urllib3/util/retry.py", line 573, in increment
    raise MaxRetryError(_pool, url, error or ResponseError(cause))
urllib3.exceptions.MaxRetryError: HTTPSConnectionPool(host='api.wandb.ai', port=443): Max retries exceeded with url: /graphql (Caused by ProxyError('Cannot connect to proxy.', timeout('_ssl.c:1106: The handshake operation timed out')))

During handling of the above exception, another exception occurred:

Traceback (most recent call last):
  File "/home/runnphoenix/anaconda3/lib/python3.8/site-packages/wandb/sdk/lib/retry.py", line 102, in __call__
    result = self._call_fn(*args, **kwargs)
  File "/home/runnphoenix/anaconda3/lib/python3.8/site-packages/wandb/sdk/internal/internal_api.py", line 141, in execute
    return self.client.execute(*args, **kwargs)
  File "/home/runnphoenix/anaconda3/lib/python3.8/site-packages/wandb/vendor/gql-0.2.0/gql/client.py", line 52, in execute
    result = self._get_result(document, *args, **kwargs)
  File "/home/runnphoenix/anaconda3/lib/python3.8/site-packages/wandb/vendor/gql-0.2.0/gql/client.py", line 60, in _get_result
    return self.transport.execute(document, *args, **kwargs)
  File "/home/runnphoenix/anaconda3/lib/python3.8/site-packages/wandb/vendor/gql-0.2.0/gql/transport/requests.py", line 38, in execute
    request = requests.post(self.url, **post_args)
  File "/home/runnphoenix/anaconda3/lib/python3.8/site-packages/requests/api.py", line 119, in post
    return request('post', url, data=data, json=json, **kwargs)
  File "/home/runnphoenix/anaconda3/lib/python3.8/site-packages/requests/api.py", line 61, in request
    return session.request(method=method, url=url, **kwargs)
  File "/home/runnphoenix/anaconda3/lib/python3.8/site-packages/requests/sessions.py", line 542, in request
    resp = self.send(prep, **send_kwargs)
  File "/home/runnphoenix/anaconda3/lib/python3.8/site-packages/requests/sessions.py", line 655, in send
    r = adapter.send(request, **kwargs)
  File "/home/runnphoenix/anaconda3/lib/python3.8/site-packages/requests/adapters.py", line 510, in send
    raise ProxyError(e, request=request)
requests.exceptions.ProxyError: HTTPSConnectionPool(host='api.wandb.ai', port=443): Max retries exceeded with url: /graphql (Caused by ProxyError('Cannot connect to proxy.', timeout('_ssl.c:1106: The handshake operation timed out')))
2022-01-02 23:17:33,171 ERROR   Thread-12 :53838 [internal_api.py:upload_file():1546] upload_file exception https://storage.googleapis.com/wandb-production.appspot.com/runnphoenix/Flatland-wandb_default/3a9bxb0q/config.yaml?Expires=1641223033&GoogleAccessId=wandb-production%40appspot.gserviceaccount.com&Signature=hxUTrAdoM%2FONF98BfmdbjY%2F1X73tUyCTolSU6vCX1D%2Be7RT74c66zJfmm47qWN5DYGZFOhrvTEkZ8Kf0QVlKfFXjEIIr65ISPGHBcZxOv7Jepfs2FbOdJuGuSCpxMnZLS7UzBS8B1eu9Xiz5bL4ZLavKRh3fZ4QPFgC7XRiKyb%2FS4vbz2dTam8ZSKAxwXwouoenzcN6FTQGbxYTJkh7acgtZ%2B26W%2Bml4qJiXd2paZdhQdeCcYtm3xFk32JmIq0jmh5iuW79UKJf31ey053CR2FMk7FTjPN%2B9ye5JvrXnHEQ7aaL3HaMZODfWGR37RfTI5Dg6%2B2qowoYbyv6hXirVZA%3D%3D HTTPSConnectionPool(host='storage.googleapis.com', port=443): Max retries exceeded with url: /wandb-production.appspot.com/runnphoenix/Flatland-wandb_default/3a9bxb0q/config.yaml?Expires=1641223033&GoogleAccessId=wandb-production%40appspot.gserviceaccount.com&Signature=hxUTrAdoM%2FONF98BfmdbjY%2F1X73tUyCTolSU6vCX1D%2Be7RT74c66zJfmm47qWN5DYGZFOhrvTEkZ8Kf0QVlKfFXjEIIr65ISPGHBcZxOv7Jepfs2FbOdJuGuSCpxMnZLS7UzBS8B1eu9Xiz5bL4ZLavKRh3fZ4QPFgC7XRiKyb%2FS4vbz2dTam8ZSKAxwXwouoenzcN6FTQGbxYTJkh7acgtZ%2B26W%2Bml4qJiXd2paZdhQdeCcYtm3xFk32JmIq0jmh5iuW79UKJf31ey053CR2FMk7FTjPN%2B9ye5JvrXnHEQ7aaL3HaMZODfWGR37RfTI5Dg6%2B2qowoYbyv6hXirVZA%3D%3D (Caused by ProxyError('Cannot connect to proxy.', OSError(0, 'Error')))
2022-01-02 23:17:33,172 ERROR   Thread-16 :53838 [internal_api.py:upload_file():1546] upload_file exception https://storage.googleapis.com/wandb-production.appspot.com/runnphoenix/Flatland-wandb_default/3a9bxb0q/conda-environment.yaml?Expires=1641223034&GoogleAccessId=wandb-production%40appspot.gserviceaccount.com&Signature=tCZKtgdIRowfFCU7eSo169nlNMNR5VojcIDJHlYDDduXN2U664HolQU5HJHdOjXIEqeziGRSveleWVygw3QUymYjdH6l0HzUH5FaV3z5STEswTFiNxXXsRwyzDN5lFjZezoU%2FlCtWxq%2FHnY7VWzHst3qn8lafCcPbAWdW7bzqPtJxZshcSHOkzGoEWbK24n7zN5CEsqm3xxjNsdZgXs%2BxV3S3W%2F2tl6%2BDz9GrjauzQFRmj%2FD4nswPOayDoTfDiTPuTFkF3Ad7hpsOiGIRh3YHgGU5%2BT3JvCfTocTBjckomOZWNO1d6OKb8JcaM7MHsrtffV3mXUBvzpcR3njhs8ADA%3D%3D HTTPSConnectionPool(host='storage.googleapis.com', port=443): Max retries exceeded with url: /wandb-production.appspot.com/runnphoenix/Flatland-wandb_default/3a9bxb0q/conda-environment.yaml?Expires=1641223034&GoogleAccessId=wandb-production%40appspot.gserviceaccount.com&Signature=tCZKtgdIRowfFCU7eSo169nlNMNR5VojcIDJHlYDDduXN2U664HolQU5HJHdOjXIEqeziGRSveleWVygw3QUymYjdH6l0HzUH5FaV3z5STEswTFiNxXXsRwyzDN5lFjZezoU%2FlCtWxq%2FHnY7VWzHst3qn8lafCcPbAWdW7bzqPtJxZshcSHOkzGoEWbK24n7zN5CEsqm3xxjNsdZgXs%2BxV3S3W%2F2tl6%2BDz9GrjauzQFRmj%2FD4nswPOayDoTfDiTPuTFkF3Ad7hpsOiGIRh3YHgGU5%2BT3JvCfTocTBjckomOZWNO1d6OKb8JcaM7MHsrtffV3mXUBvzpcR3njhs8ADA%3D%3D (Caused by ProxyError('Cannot connect to proxy.', OSError(0, 'Error')))
2022-01-02 23:17:33,173 ERROR   Thread-15 :53838 [internal_api.py:upload_file():1546] upload_file exception https://storage.googleapis.com/wandb-production.appspot.com/runnphoenix/Flatland-wandb_default/3a9bxb0q/wandb-summary.json?Expires=1641223033&GoogleAccessId=wandb-production%40appspot.gserviceaccount.com&Signature=gu6co8kYt%2BtFgq4pSntxHpFP0Qt8G5K2%2F6EGtz8OCb6uKFa38deetIcvSqCwaPosDFy0DC3D3d7QVgXU%2BRX3FPvhN6ZU79Je%2B%2FhieerjlE4aaeRAY3LEg55GCNwAs0Zrd1I0CditA50GsJdCrWzNioYCd9PvezcBqKhkbZ7K9xlt57FwboJUMpmAC9gy8eRVs0FN90n%2BkgdakWtCL2VGFVToj2Sxj2GJtqzhy6MSvhe1MmPE8ZiwBJ8pFrQZJST1f5O1NMjEOzFYWwaSqw1g8oXxSQaHRbWBpatHBgms%2F7u2KxysgXF658C%2Bo4RplO9OPSwWN4aARHZA%2FRYfF7UASQ%3D%3D HTTPSConnectionPool(host='storage.googleapis.com', port=443): Max retries exceeded with url: /wandb-production.appspot.com/runnphoenix/Flatland-wandb_default/3a9bxb0q/wandb-summary.json?Expires=1641223033&GoogleAccessId=wandb-production%40appspot.gserviceaccount.com&Signature=gu6co8kYt%2BtFgq4pSntxHpFP0Qt8G5K2%2F6EGtz8OCb6uKFa38deetIcvSqCwaPosDFy0DC3D3d7QVgXU%2BRX3FPvhN6ZU79Je%2B%2FhieerjlE4aaeRAY3LEg55GCNwAs0Zrd1I0CditA50GsJdCrWzNioYCd9PvezcBqKhkbZ7K9xlt57FwboJUMpmAC9gy8eRVs0FN90n%2BkgdakWtCL2VGFVToj2Sxj2GJtqzhy6MSvhe1MmPE8ZiwBJ8pFrQZJST1f5O1NMjEOzFYWwaSqw1g8oXxSQaHRbWBpatHBgms%2F7u2KxysgXF658C%2Bo4RplO9OPSwWN4aARHZA%2FRYfF7UASQ%3D%3D (Caused by ProxyError('Cannot connect to proxy.', OSError(0, 'Error')))
2022-01-02 23:17:39,960 INFO    Thread-12 :53838 [upload_job.py:push():137] Uploaded file /home/runnphoenix/work/flatland-rl/rainbow/wandb/run-20220102_231346-3a9bxb0q/files/config.yaml
2022-01-02 23:17:40,518 INFO    Thread-15 :53838 [upload_job.py:push():137] Uploaded file /home/runnphoenix/work/flatland-rl/rainbow/wandb/run-20220102_231346-3a9bxb0q/files/wandb-summary.json
2022-01-02 23:17:40,678 INFO    Thread-16 :53838 [upload_job.py:push():137] Uploaded file /home/runnphoenix/work/flatland-rl/rainbow/wandb/run-20220102_231346-3a9bxb0q/files/conda-environment.yaml
2022-01-02 23:17:41,622 INFO    Thread-14 :53838 [upload_job.py:push():137] Uploaded file /home/runnphoenix/work/flatland-rl/rainbow/wandb/run-20220102_231346-3a9bxb0q/files/output.log
2022-01-02 23:17:43,831 INFO    Thread-13 :53838 [upload_job.py:push():137] Uploaded file /home/runnphoenix/work/flatland-rl/rainbow/wandb/run-20220102_231346-3a9bxb0q/files/requirements.txt
2022-01-02 23:17:44,334 INFO    MainThread:53838 [internal.py:handle_exit():77] Internal process exited
