2021-12-24 11:27:14,861 INFO    MainThread:2215707 [wandb_setup.py:_flush():71] setting env: {}
2021-12-24 11:27:14,861 INFO    MainThread:2215707 [wandb_setup.py:_flush():71] setting login settings: {}
2021-12-24 11:27:14,861 INFO    MainThread:2215707 [wandb_init.py:_log_setup():357] Logging user logs to /home/runnphoenix/work/flatland-rl/rainbow/wandb/run-20211224_112714-21g24926/logs/debug.log
2021-12-24 11:27:14,861 INFO    MainThread:2215707 [wandb_init.py:_log_setup():358] Logging internal logs to /home/runnphoenix/work/flatland-rl/rainbow/wandb/run-20211224_112714-21g24926/logs/debug-internal.log
2021-12-24 11:27:14,861 INFO    MainThread:2215707 [wandb_init.py:init():390] calling init triggers
2021-12-24 11:27:14,861 INFO    MainThread:2215707 [wandb_init.py:init():395] wandb.init called with sweep_config: {}
config: {'width': 25, 'height': 25, 'num_agents': 1, 'max_num_cities': 2, 'seed': 1, 'grid_mode': False, 'max_rails_between_cities': 2, 'max_rails_in_city': 4, 'malfunction_rate': 0, 'min_duration': 20, 'max_duration': 50, 'observation_builder': 'GraphObsForRailEnv', 'predictor': 'ShortestPathPredictorForRailEnv', 'view_semiwidth': 7, 'view_height': 30, 'offset': 25, 'observation_depth': 3, 'num_episodes': 200, 'start_epoch': 0, 'max_steps': 300, 'eps': 1, 'debug_print': False, 'load_memory': False, 'evaluation_episodes': 3, 'render': False, 'evaluation_interval': 10, 'save_model_interval': 50, 'start_lr_decay': 150, 'eps_decay': 0.999, 'learning_rate': 0.02, 'learning_rate_decay': 0.5, 'learning_rate_decay_policy': 0.5, 'run_title': 'first_run', 'wandb_project_name': 'wandb_default', 'model_path': 'test_results/', 'model_name': '', 'gat_layers': 3, 'flow': 'source_to_target', 'resume_weights': True, 'batch_norm': False, 'dropout_rate': 0.8, 'attention_heads': 4, 'batch_size': 128, 'use_stop_action': False, 'done_reward': 0, 'deadlock_reward': -1000, 'reward_scaling': 0.1}
2021-12-24 11:27:14,861 INFO    MainThread:2215707 [wandb_init.py:init():435] starting backend
2021-12-24 11:27:14,861 INFO    MainThread:2215707 [backend.py:_multiprocessing_setup():95] multiprocessing start_methods=fork,spawn,forkserver, using: spawn
2021-12-24 11:27:14,874 INFO    MainThread:2215707 [backend.py:ensure_launched():199] starting backend process...
2021-12-24 11:27:14,883 INFO    MainThread:2215707 [backend.py:ensure_launched():204] started backend process with pid: 2215877
2021-12-24 11:27:14,884 INFO    MainThread:2215707 [wandb_init.py:init():444] backend started and connected
2021-12-24 11:27:14,886 INFO    MainThread:2215707 [wandb_init.py:init():503] updated telemetry
2021-12-24 11:27:14,911 INFO    MainThread:2215707 [wandb_init.py:init():533] communicating current version
2021-12-24 11:27:18,684 INFO    MainThread:2215707 [wandb_init.py:init():538] got version response 
2021-12-24 11:27:18,684 INFO    MainThread:2215707 [wandb_init.py:init():548] communicating run to backend with 30 second timeout
2021-12-24 11:27:43,329 ERROR   Thread-1  :2215707 [retry.py:__call__():126] Retry attempt failed:
Traceback (most recent call last):
  File "/home/runnphoenix/anaconda3/lib/python3.8/site-packages/urllib3/connectionpool.py", line 696, in urlopen
    self._prepare_proxy(conn)
  File "/home/runnphoenix/anaconda3/lib/python3.8/site-packages/urllib3/connectionpool.py", line 964, in _prepare_proxy
    conn.connect()
  File "/home/runnphoenix/anaconda3/lib/python3.8/site-packages/urllib3/connection.py", line 411, in connect
    self.sock = ssl_wrap_socket(
  File "/home/runnphoenix/anaconda3/lib/python3.8/site-packages/urllib3/util/ssl_.py", line 428, in ssl_wrap_socket
    ssl_sock = _ssl_wrap_socket_impl(
  File "/home/runnphoenix/anaconda3/lib/python3.8/site-packages/urllib3/util/ssl_.py", line 472, in _ssl_wrap_socket_impl
    return ssl_context.wrap_socket(sock, server_hostname=server_hostname)
  File "/home/runnphoenix/anaconda3/lib/python3.8/ssl.py", line 500, in wrap_socket
    return self.sslsocket_class._create(
  File "/home/runnphoenix/anaconda3/lib/python3.8/ssl.py", line 1040, in _create
    self.do_handshake()
  File "/home/runnphoenix/anaconda3/lib/python3.8/ssl.py", line 1309, in do_handshake
    self._sslobj.do_handshake()
socket.timeout: _ssl.c:1106: The handshake operation timed out

During handling of the above exception, another exception occurred:

Traceback (most recent call last):
  File "/home/runnphoenix/anaconda3/lib/python3.8/site-packages/requests/adapters.py", line 439, in send
    resp = conn.urlopen(
  File "/home/runnphoenix/anaconda3/lib/python3.8/site-packages/urllib3/connectionpool.py", line 755, in urlopen
    retries = retries.increment(
  File "/home/runnphoenix/anaconda3/lib/python3.8/site-packages/urllib3/util/retry.py", line 573, in increment
    raise MaxRetryError(_pool, url, error or ResponseError(cause))
urllib3.exceptions.MaxRetryError: HTTPSConnectionPool(host='api.wandb.ai', port=443): Max retries exceeded with url: /graphql (Caused by ProxyError('Cannot connect to proxy.', timeout('_ssl.c:1106: The handshake operation timed out')))

During handling of the above exception, another exception occurred:

Traceback (most recent call last):
  File "/home/runnphoenix/anaconda3/lib/python3.8/site-packages/wandb/sdk/lib/retry.py", line 102, in __call__
    result = self._call_fn(*args, **kwargs)
  File "/home/runnphoenix/anaconda3/lib/python3.8/site-packages/wandb/sdk/internal/internal_api.py", line 141, in execute
    return self.client.execute(*args, **kwargs)
  File "/home/runnphoenix/anaconda3/lib/python3.8/site-packages/wandb/vendor/gql-0.2.0/gql/client.py", line 52, in execute
    result = self._get_result(document, *args, **kwargs)
  File "/home/runnphoenix/anaconda3/lib/python3.8/site-packages/wandb/vendor/gql-0.2.0/gql/client.py", line 60, in _get_result
    return self.transport.execute(document, *args, **kwargs)
  File "/home/runnphoenix/anaconda3/lib/python3.8/site-packages/wandb/vendor/gql-0.2.0/gql/transport/requests.py", line 38, in execute
    request = requests.post(self.url, **post_args)
  File "/home/runnphoenix/anaconda3/lib/python3.8/site-packages/requests/api.py", line 119, in post
    return request('post', url, data=data, json=json, **kwargs)
  File "/home/runnphoenix/anaconda3/lib/python3.8/site-packages/requests/api.py", line 61, in request
    return session.request(method=method, url=url, **kwargs)
  File "/home/runnphoenix/anaconda3/lib/python3.8/site-packages/requests/sessions.py", line 542, in request
    resp = self.send(prep, **send_kwargs)
  File "/home/runnphoenix/anaconda3/lib/python3.8/site-packages/requests/sessions.py", line 655, in send
    r = adapter.send(request, **kwargs)
  File "/home/runnphoenix/anaconda3/lib/python3.8/site-packages/requests/adapters.py", line 510, in send
    raise ProxyError(e, request=request)
requests.exceptions.ProxyError: HTTPSConnectionPool(host='api.wandb.ai', port=443): Max retries exceeded with url: /graphql (Caused by ProxyError('Cannot connect to proxy.', timeout('_ssl.c:1106: The handshake operation timed out')))
2021-12-24 11:27:48,686 INFO    MainThread:2215707 [interface_queue.py:_communicate_run():336] couldn't get run from backend
2021-12-24 11:27:48,686 ERROR   MainThread:2215707 [wandb_init.py:init():553] backend process timed out
2021-12-24 11:27:48,686 ERROR   MainThread:2215707 [wandb_init.py:init():562] encountered error: Error communicating with wandb process
try: wandb.init(settings=wandb.Settings(start_method='fork'))
or:  wandb.init(settings=wandb.Settings(start_method='thread'))
For more info see: https://docs.wandb.ai/library/init#init-start-error
2021-12-24 11:28:38,700 INFO    MainThread:2215707 [wandb_init.py:teardown():205] tearing down wandb.init
