2022-01-26 22:35:08,807 INFO    MainThread:18758 [internal.py:wandb_internal():87] W&B internal server running at pid: 18758, started at: 2022-01-26 22:35:08.807534
2022-01-26 22:35:08,809 INFO    WriterThread:18758 [datastore.py:open_for_write():77] open: /home/runnphoenix/work/flatland-rl/rainbow/wandb/run-20220126_223507-1zml0lax/run-1zml0lax.wandb
2022-01-26 22:35:08,810 DEBUG   HandlerThread:18758 [handler.py:handle_request():130] handle_request: check_version
2022-01-26 22:35:08,810 DEBUG   SenderThread:18758 [sender.py:send():238] send: header
2022-01-26 22:35:08,811 DEBUG   SenderThread:18758 [sender.py:send_request():252] send_request: check_version
2022-01-26 22:35:08,815 DEBUG   SenderThread:18758 [sender.py:send():238] send: run
2022-01-26 22:35:10,084 WARNING MainThread:18758 [internal.py:wandb_internal():146] Internal process interrupt: 1
2022-01-26 22:35:12,363 ERROR   SenderThread:18758 [retry.py:__call__():126] Retry attempt failed:
Traceback (most recent call last):
  File "/home/runnphoenix/anaconda3/lib/python3.8/site-packages/urllib3/connection.py", line 169, in _new_conn
    conn = connection.create_connection(
  File "/home/runnphoenix/anaconda3/lib/python3.8/site-packages/urllib3/util/connection.py", line 96, in create_connection
    raise err
  File "/home/runnphoenix/anaconda3/lib/python3.8/site-packages/urllib3/util/connection.py", line 86, in create_connection
    sock.connect(sa)
ConnectionRefusedError: [Errno 111] Connection refused

During handling of the above exception, another exception occurred:

Traceback (most recent call last):
  File "/home/runnphoenix/anaconda3/lib/python3.8/site-packages/urllib3/connectionpool.py", line 696, in urlopen
    self._prepare_proxy(conn)
  File "/home/runnphoenix/anaconda3/lib/python3.8/site-packages/urllib3/connectionpool.py", line 964, in _prepare_proxy
    conn.connect()
  File "/home/runnphoenix/anaconda3/lib/python3.8/site-packages/urllib3/connection.py", line 353, in connect
    conn = self._new_conn()
  File "/home/runnphoenix/anaconda3/lib/python3.8/site-packages/urllib3/connection.py", line 181, in _new_conn
    raise NewConnectionError(
urllib3.exceptions.NewConnectionError: <urllib3.connection.HTTPSConnection object at 0x7f9f95349eb0>: Failed to establish a new connection: [Errno 111] Connection refused

During handling of the above exception, another exception occurred:

Traceback (most recent call last):
  File "/home/runnphoenix/anaconda3/lib/python3.8/site-packages/requests/adapters.py", line 439, in send
    resp = conn.urlopen(
  File "/home/runnphoenix/anaconda3/lib/python3.8/site-packages/urllib3/connectionpool.py", line 755, in urlopen
    retries = retries.increment(
  File "/home/runnphoenix/anaconda3/lib/python3.8/site-packages/urllib3/util/retry.py", line 573, in increment
    raise MaxRetryError(_pool, url, error or ResponseError(cause))
urllib3.exceptions.MaxRetryError: HTTPSConnectionPool(host='api.wandb.ai', port=443): Max retries exceeded with url: /graphql (Caused by ProxyError('Cannot connect to proxy.', NewConnectionError('<urllib3.connection.HTTPSConnection object at 0x7f9f95349eb0>: Failed to establish a new connection: [Errno 111] Connection refused')))

During handling of the above exception, another exception occurred:

Traceback (most recent call last):
  File "/home/runnphoenix/anaconda3/lib/python3.8/site-packages/wandb/sdk/lib/retry.py", line 102, in __call__
    result = self._call_fn(*args, **kwargs)
  File "/home/runnphoenix/anaconda3/lib/python3.8/site-packages/wandb/sdk/internal/internal_api.py", line 141, in execute
    return self.client.execute(*args, **kwargs)
  File "/home/runnphoenix/anaconda3/lib/python3.8/site-packages/wandb/vendor/gql-0.2.0/gql/client.py", line 52, in execute
    result = self._get_result(document, *args, **kwargs)
  File "/home/runnphoenix/anaconda3/lib/python3.8/site-packages/wandb/vendor/gql-0.2.0/gql/client.py", line 60, in _get_result
    return self.transport.execute(document, *args, **kwargs)
  File "/home/runnphoenix/anaconda3/lib/python3.8/site-packages/wandb/vendor/gql-0.2.0/gql/transport/requests.py", line 38, in execute
    request = requests.post(self.url, **post_args)
  File "/home/runnphoenix/anaconda3/lib/python3.8/site-packages/requests/api.py", line 119, in post
    return request('post', url, data=data, json=json, **kwargs)
  File "/home/runnphoenix/anaconda3/lib/python3.8/site-packages/requests/api.py", line 61, in request
    return session.request(method=method, url=url, **kwargs)
  File "/home/runnphoenix/anaconda3/lib/python3.8/site-packages/requests/sessions.py", line 542, in request
    resp = self.send(prep, **send_kwargs)
  File "/home/runnphoenix/anaconda3/lib/python3.8/site-packages/requests/sessions.py", line 655, in send
    r = adapter.send(request, **kwargs)
  File "/home/runnphoenix/anaconda3/lib/python3.8/site-packages/requests/adapters.py", line 510, in send
    raise ProxyError(e, request=request)
requests.exceptions.ProxyError: HTTPSConnectionPool(host='api.wandb.ai', port=443): Max retries exceeded with url: /graphql (Caused by ProxyError('Cannot connect to proxy.', NewConnectionError('<urllib3.connection.HTTPSConnection object at 0x7f9f95349eb0>: Failed to establish a new connection: [Errno 111] Connection refused')))
2022-01-26 22:35:46,415 WARNING MainThread:18758 [internal.py:wandb_internal():146] Internal process interrupt: 2
2022-01-26 22:35:46,415 ERROR   MainThread:18758 [internal.py:wandb_internal():149] Internal process interrupted.
2022-01-26 22:35:46,828 INFO    WriterThread:18758 [datastore.py:close():281] close: /home/runnphoenix/work/flatland-rl/rainbow/wandb/run-20220126_223507-1zml0lax/run-1zml0lax.wandb
2022-01-26 22:35:46,857 INFO    HandlerThread:18758 [handler.py:finish():731] shutting down handler
2022-01-26 22:36:36,072 INFO    SenderThread:18758 [dir_watcher.py:__init__():169] watching files in: /home/runnphoenix/work/flatland-rl/rainbow/wandb/run-20220126_223507-1zml0lax/files
2022-01-26 22:36:36,072 INFO    SenderThread:18758 [sender.py:_start_run_threads():825] run started: 1zml0lax with start time 1643207707
2022-01-26 22:36:36,072 INFO    SenderThread:18758 [sender.py:finish():1091] shutting down sender
2022-01-26 22:36:36,072 INFO    SenderThread:18758 [dir_watcher.py:finish():283] shutting down directory watcher
2022-01-26 22:36:37,073 INFO    SenderThread:18758 [dir_watcher.py:finish():313] scan: /home/runnphoenix/work/flatland-rl/rainbow/wandb/run-20220126_223507-1zml0lax/files
2022-01-26 22:36:37,073 INFO    SenderThread:18758 [dir_watcher.py:finish():327] scan save: /home/runnphoenix/work/flatland-rl/rainbow/wandb/run-20220126_223507-1zml0lax/files/config.yaml config.yaml
2022-01-26 22:36:37,073 INFO    SenderThread:18758 [file_pusher.py:finish():177] shutting down file pusher
2022-01-26 22:36:37,073 INFO    SenderThread:18758 [file_pusher.py:join():182] waiting for file pusher
2022-01-26 22:36:49,173 INFO    Thread-10 :18758 [upload_job.py:push():137] Uploaded file /home/runnphoenix/work/flatland-rl/rainbow/wandb/run-20220126_223507-1zml0lax/files/config.yaml
2022-01-26 22:36:50,300 INFO    MainThread:18758 [internal.py:handle_exit():77] Internal process exited
