2022-01-10 00:31:53,046 INFO    MainThread:114017 [internal.py:wandb_internal():87] W&B internal server running at pid: 114017, started at: 2022-01-10 00:31:53.045975
2022-01-10 00:31:53,048 DEBUG   HandlerThread:114017 [handler.py:handle_request():130] handle_request: check_version
2022-01-10 00:31:53,048 INFO    WriterThread:114017 [datastore.py:open_for_write():77] open: /home/runnphoenix/work/flatland-rl/rainbow/wandb/run-20220110_003152-1ywmowlo/run-1ywmowlo.wandb
2022-01-10 00:31:53,049 DEBUG   SenderThread:114017 [sender.py:send():238] send: header
2022-01-10 00:31:53,049 DEBUG   SenderThread:114017 [sender.py:send_request():252] send_request: check_version
2022-01-10 00:31:54,567 DEBUG   SenderThread:114017 [sender.py:send():238] send: run
2022-01-10 00:32:24,568 DEBUG   HandlerThread:114017 [handler.py:handle_request():130] handle_request: shutdown
2022-01-10 00:32:24,568 INFO    HandlerThread:114017 [handler.py:finish():731] shutting down handler
2022-01-10 00:32:24,575 INFO    WriterThread:114017 [datastore.py:close():281] close: /home/runnphoenix/work/flatland-rl/rainbow/wandb/run-20220110_003152-1ywmowlo/run-1ywmowlo.wandb
2022-01-10 00:32:38,809 ERROR   SenderThread:114017 [retry.py:__call__():126] Retry attempt failed:
Traceback (most recent call last):
  File "/home/runnphoenix/anaconda3/lib/python3.8/site-packages/urllib3/connectionpool.py", line 445, in _make_request
    six.raise_from(e, None)
  File "<string>", line 3, in raise_from
  File "/home/runnphoenix/anaconda3/lib/python3.8/site-packages/urllib3/connectionpool.py", line 440, in _make_request
    httplib_response = conn.getresponse()
  File "/home/runnphoenix/anaconda3/lib/python3.8/http/client.py", line 1347, in getresponse
    response.begin()
  File "/home/runnphoenix/anaconda3/lib/python3.8/http/client.py", line 307, in begin
    version, status, reason = self._read_status()
  File "/home/runnphoenix/anaconda3/lib/python3.8/http/client.py", line 268, in _read_status
    line = str(self.fp.readline(_MAXLINE + 1), "iso-8859-1")
  File "/home/runnphoenix/anaconda3/lib/python3.8/socket.py", line 669, in readinto
    return self._sock.recv_into(b)
  File "/home/runnphoenix/anaconda3/lib/python3.8/ssl.py", line 1241, in recv_into
    return self.read(nbytes, buffer)
  File "/home/runnphoenix/anaconda3/lib/python3.8/ssl.py", line 1099, in read
    return self._sslobj.read(len, buffer)
socket.timeout: The read operation timed out

During handling of the above exception, another exception occurred:

Traceback (most recent call last):
  File "/home/runnphoenix/anaconda3/lib/python3.8/site-packages/requests/adapters.py", line 439, in send
    resp = conn.urlopen(
  File "/home/runnphoenix/anaconda3/lib/python3.8/site-packages/urllib3/connectionpool.py", line 755, in urlopen
    retries = retries.increment(
  File "/home/runnphoenix/anaconda3/lib/python3.8/site-packages/urllib3/util/retry.py", line 531, in increment
    raise six.reraise(type(error), error, _stacktrace)
  File "/home/runnphoenix/anaconda3/lib/python3.8/site-packages/urllib3/packages/six.py", line 735, in reraise
    raise value
  File "/home/runnphoenix/anaconda3/lib/python3.8/site-packages/urllib3/connectionpool.py", line 699, in urlopen
    httplib_response = self._make_request(
  File "/home/runnphoenix/anaconda3/lib/python3.8/site-packages/urllib3/connectionpool.py", line 447, in _make_request
    self._raise_timeout(err=e, url=url, timeout_value=read_timeout)
  File "/home/runnphoenix/anaconda3/lib/python3.8/site-packages/urllib3/connectionpool.py", line 336, in _raise_timeout
    raise ReadTimeoutError(
urllib3.exceptions.ReadTimeoutError: HTTPSConnectionPool(host='api.wandb.ai', port=443): Read timed out. (read timeout=10)

During handling of the above exception, another exception occurred:

Traceback (most recent call last):
  File "/home/runnphoenix/anaconda3/lib/python3.8/site-packages/wandb/sdk/lib/retry.py", line 102, in __call__
    result = self._call_fn(*args, **kwargs)
  File "/home/runnphoenix/anaconda3/lib/python3.8/site-packages/wandb/sdk/internal/internal_api.py", line 141, in execute
    return self.client.execute(*args, **kwargs)
  File "/home/runnphoenix/anaconda3/lib/python3.8/site-packages/wandb/vendor/gql-0.2.0/gql/client.py", line 52, in execute
    result = self._get_result(document, *args, **kwargs)
  File "/home/runnphoenix/anaconda3/lib/python3.8/site-packages/wandb/vendor/gql-0.2.0/gql/client.py", line 60, in _get_result
    return self.transport.execute(document, *args, **kwargs)
  File "/home/runnphoenix/anaconda3/lib/python3.8/site-packages/wandb/vendor/gql-0.2.0/gql/transport/requests.py", line 38, in execute
    request = requests.post(self.url, **post_args)
  File "/home/runnphoenix/anaconda3/lib/python3.8/site-packages/requests/api.py", line 119, in post
    return request('post', url, data=data, json=json, **kwargs)
  File "/home/runnphoenix/anaconda3/lib/python3.8/site-packages/requests/api.py", line 61, in request
    return session.request(method=method, url=url, **kwargs)
  File "/home/runnphoenix/anaconda3/lib/python3.8/site-packages/requests/sessions.py", line 542, in request
    resp = self.send(prep, **send_kwargs)
  File "/home/runnphoenix/anaconda3/lib/python3.8/site-packages/requests/sessions.py", line 655, in send
    r = adapter.send(request, **kwargs)
  File "/home/runnphoenix/anaconda3/lib/python3.8/site-packages/requests/adapters.py", line 529, in send
    raise ReadTimeout(e, request=request)
requests.exceptions.ReadTimeout: HTTPSConnectionPool(host='api.wandb.ai', port=443): Read timed out. (read timeout=10)
2022-01-10 00:33:10,651 INFO    SenderThread:114017 [dir_watcher.py:__init__():169] watching files in: /home/runnphoenix/work/flatland-rl/rainbow/wandb/run-20220110_003152-1ywmowlo/files
2022-01-10 00:33:10,652 INFO    SenderThread:114017 [sender.py:_start_run_threads():825] run started: 1ywmowlo with start time 1641745912
2022-01-10 00:33:10,652 INFO    SenderThread:114017 [sender.py:finish():1091] shutting down sender
2022-01-10 00:33:10,652 INFO    SenderThread:114017 [dir_watcher.py:finish():283] shutting down directory watcher
2022-01-10 00:33:11,652 INFO    SenderThread:114017 [dir_watcher.py:finish():313] scan: /home/runnphoenix/work/flatland-rl/rainbow/wandb/run-20220110_003152-1ywmowlo/files
2022-01-10 00:33:11,652 INFO    SenderThread:114017 [dir_watcher.py:finish():327] scan save: /home/runnphoenix/work/flatland-rl/rainbow/wandb/run-20220110_003152-1ywmowlo/files/config.yaml config.yaml
2022-01-10 00:33:11,652 INFO    SenderThread:114017 [file_pusher.py:finish():177] shutting down file pusher
2022-01-10 00:33:11,653 INFO    SenderThread:114017 [file_pusher.py:join():182] waiting for file pusher
2022-01-10 00:33:16,132 INFO    Thread-10 :114017 [upload_job.py:push():137] Uploaded file /home/runnphoenix/work/flatland-rl/rainbow/wandb/run-20220110_003152-1ywmowlo/files/config.yaml
2022-01-10 00:33:20,885 INFO    MainThread:114017 [internal.py:handle_exit():77] Internal process exited
