2021-11-18 10:46:37,557 INFO    MainThread:180107 [internal.py:wandb_internal():87] W&B internal server running at pid: 180107, started at: 2021-11-18 10:46:37.556944
2021-11-18 10:46:37,559 INFO    WriterThread:180107 [datastore.py:open_for_write():77] open: /home/runnphoenix/work/flatland-rl/rainbow/wandb/run-20211118_104636-3bv6nf64/run-3bv6nf64.wandb
2021-11-18 10:46:37,559 DEBUG   SenderThread:180107 [sender.py:send():238] send: header
2021-11-18 10:46:37,560 DEBUG   HandlerThread:180107 [handler.py:handle_request():130] handle_request: check_version
2021-11-18 10:46:37,560 DEBUG   SenderThread:180107 [sender.py:send_request():252] send_request: check_version
2021-11-18 10:46:37,565 DEBUG   SenderThread:180107 [sender.py:send():238] send: run
2021-11-18 10:46:40,969 ERROR   SenderThread:180107 [retry.py:__call__():126] Retry attempt failed:
Traceback (most recent call last):
  File "/home/runnphoenix/anaconda3/lib/python3.8/site-packages/urllib3/connection.py", line 169, in _new_conn
    conn = connection.create_connection(
  File "/home/runnphoenix/anaconda3/lib/python3.8/site-packages/urllib3/util/connection.py", line 96, in create_connection
    raise err
  File "/home/runnphoenix/anaconda3/lib/python3.8/site-packages/urllib3/util/connection.py", line 86, in create_connection
    sock.connect(sa)
ConnectionRefusedError: [Errno 111] Connection refused

During handling of the above exception, another exception occurred:

Traceback (most recent call last):
  File "/home/runnphoenix/anaconda3/lib/python3.8/site-packages/urllib3/connectionpool.py", line 696, in urlopen
    self._prepare_proxy(conn)
  File "/home/runnphoenix/anaconda3/lib/python3.8/site-packages/urllib3/connectionpool.py", line 964, in _prepare_proxy
    conn.connect()
  File "/home/runnphoenix/anaconda3/lib/python3.8/site-packages/urllib3/connection.py", line 353, in connect
    conn = self._new_conn()
  File "/home/runnphoenix/anaconda3/lib/python3.8/site-packages/urllib3/connection.py", line 181, in _new_conn
    raise NewConnectionError(
urllib3.exceptions.NewConnectionError: <urllib3.connection.HTTPSConnection object at 0x7f5727021b20>: Failed to establish a new connection: [Errno 111] Connection refused

During handling of the above exception, another exception occurred:

Traceback (most recent call last):
  File "/home/runnphoenix/anaconda3/lib/python3.8/site-packages/requests/adapters.py", line 439, in send
    resp = conn.urlopen(
  File "/home/runnphoenix/anaconda3/lib/python3.8/site-packages/urllib3/connectionpool.py", line 755, in urlopen
    retries = retries.increment(
  File "/home/runnphoenix/anaconda3/lib/python3.8/site-packages/urllib3/util/retry.py", line 573, in increment
    raise MaxRetryError(_pool, url, error or ResponseError(cause))
urllib3.exceptions.MaxRetryError: HTTPSConnectionPool(host='api.wandb.ai', port=443): Max retries exceeded with url: /graphql (Caused by ProxyError('Cannot connect to proxy.', NewConnectionError('<urllib3.connection.HTTPSConnection object at 0x7f5727021b20>: Failed to establish a new connection: [Errno 111] Connection refused')))

During handling of the above exception, another exception occurred:

Traceback (most recent call last):
  File "/home/runnphoenix/anaconda3/lib/python3.8/site-packages/wandb/sdk/lib/retry.py", line 102, in __call__
    result = self._call_fn(*args, **kwargs)
  File "/home/runnphoenix/anaconda3/lib/python3.8/site-packages/wandb/sdk/internal/internal_api.py", line 141, in execute
    return self.client.execute(*args, **kwargs)
  File "/home/runnphoenix/anaconda3/lib/python3.8/site-packages/wandb/vendor/gql-0.2.0/gql/client.py", line 52, in execute
    result = self._get_result(document, *args, **kwargs)
  File "/home/runnphoenix/anaconda3/lib/python3.8/site-packages/wandb/vendor/gql-0.2.0/gql/client.py", line 60, in _get_result
    return self.transport.execute(document, *args, **kwargs)
  File "/home/runnphoenix/anaconda3/lib/python3.8/site-packages/wandb/vendor/gql-0.2.0/gql/transport/requests.py", line 38, in execute
    request = requests.post(self.url, **post_args)
  File "/home/runnphoenix/anaconda3/lib/python3.8/site-packages/requests/api.py", line 119, in post
    return request('post', url, data=data, json=json, **kwargs)
  File "/home/runnphoenix/anaconda3/lib/python3.8/site-packages/requests/api.py", line 61, in request
    return session.request(method=method, url=url, **kwargs)
  File "/home/runnphoenix/anaconda3/lib/python3.8/site-packages/requests/sessions.py", line 542, in request
    resp = self.send(prep, **send_kwargs)
  File "/home/runnphoenix/anaconda3/lib/python3.8/site-packages/requests/sessions.py", line 655, in send
    r = adapter.send(request, **kwargs)
  File "/home/runnphoenix/anaconda3/lib/python3.8/site-packages/requests/adapters.py", line 510, in send
    raise ProxyError(e, request=request)
requests.exceptions.ProxyError: HTTPSConnectionPool(host='api.wandb.ai', port=443): Max retries exceeded with url: /graphql (Caused by ProxyError('Cannot connect to proxy.', NewConnectionError('<urllib3.connection.HTTPSConnection object at 0x7f5727021b20>: Failed to establish a new connection: [Errno 111] Connection refused')))
2021-11-18 10:47:07,565 DEBUG   HandlerThread:180107 [handler.py:handle_request():130] handle_request: shutdown
2021-11-18 10:47:07,565 INFO    HandlerThread:180107 [handler.py:finish():731] shutting down handler
2021-11-18 10:47:07,573 INFO    WriterThread:180107 [datastore.py:close():281] close: /home/runnphoenix/work/flatland-rl/rainbow/wandb/run-20211118_104636-3bv6nf64/run-3bv6nf64.wandb
2021-11-18 10:54:50,644 INFO    MainThread:180107 [internal.py:handle_exit():77] Internal process exited
